Workbook
Name _10_12: #REF!
Name _10_15: #REF!
Name _10_20: #REF!
Name _100_110: #REF!
Name _100_150: #REF!
Name _10kg: #REF!
Name _10묶음: #REF!
Name _10미: #REF!
Name _11미: #REF!
Name _120_130: #REF!
Name _12미: #REF!
Name _12손: #REF!
Name _13미: #REF!
Name _14미: #REF!
Name _15_17: #REF!
Name _15_20: #REF!
Name _150_200: #REF!
Name _150_200B: #REF!
Name _15kg: #REF!
Name _15미: #REF!
Name _15팩: #REF!
Name _16_20: #REF!
Name _160미: #REF!
Name _16미: #REF!
Name _16손: #REF!
Name _17미: #REF!
Name _180_200미: #REF!
Name _185미: #REF!
Name _18미: #REF!
Name _1kg: #REF!
Name _1매: #REF!
Name _1번: #REF!
Name _20: #REF!
Name _20_25: #REF!
Name _20_30: #REF!
Name _200_300: #REF!
Name _200_400: #REF!
Name _20kg: #REF!
Name _20UP: #REF!
Name _20미: #REF!
Name _20손: #REF!
Name _21_25: #REF!
Name _210미: #REF!
Name _22미: #REF!
Name _23_25: #REF!
Name _24미: #REF!
Name _24손: #REF!
Name _25_30: #REF!
Name _25미: #REF!
Name _26미: #REF!
Name _28_30: #REF!
Name _28미: #REF!
Name _2kg: #REF!
Name _2L: #REF!
Name _2단: #REF!
Name _2미: #REF!
Name _2번: #REF!
Name _30_35: #REF!
Name _30_40: #REF!
Name _300: #REF!

Sheet 근무표
AM2: 관리자모드 - 영업자료조회
D3: 1 | E3: 2 | F3: 3 | G3: 4 | H3: 5 | I3: 6 | J3: 7 | K3: 8 | L3: 9 | M3: 10 | N3: 11 | O3: 12 | P3: 13 | Q3: 14 | R3: 15 | S3: 16 | T3: 17 | U3: 18 | V3: 19 | W3: 20 | X3: 21 | Y3: 22 | Z3: 23 | AA3: 24 | AB3: 25 | AC3: 26 | AD3: 27 | AE3: 28 | AF3: 29 | AG3: 30 | AH3: 31 | AI3: 근무 일수 | AK3: 근무자 명단 | AM3: NO | AN3: 매장 | AO3: 매출 | AP3: 현금 | AQ3: 카드 | AR3: 매출이익 | AS3: 매출이익률 | AT3: 일지출 | AU3: 영업이익 | AV3: 인당생산성 | AW3: 최고매출품목 | AX3: 매출액 | AY3: 근무인원 | AZ3: 팀장 | BA3: 팀원 | BB3: 팀원 | BC3: 팀원 | BD3: 팀원 | BE3: 팀원 | BF3: 팀원 | BG3: 팀원 | BH3: 팀원 | BI3: 팀원 | BJ3: 팀원 | BK3: 팀원 | BL3: 매출차액 | BM3: 일일 매입금액 집계표
C4: 요일 근무자 | AM4: 1 | AN4: ='1'!$G$2 -> 현대 | AO4: ='1'!$C$5 -> 4281000 | AP4: ='1'!$C$22 -> 1253000 | AQ4: ='1'!$C$23 -> 2983000 | AR4: ='1'!$C$15 -> 1213940 | AS4: ='1'!$C$17 -> 0.28356459 | AT4: ='1'!$C$36 -> 45000 | AU4: ='1'!$C$19 -> 1168940 | AV4: =IFERROR(AO4/AY4,0) -> 1427000 | AW4: =VLOOKUP(AX4,IF({1,0},'1'!$AI$8:'1'!$AI$75,'1'!$AD$8:$AD$75),2,0) -> 꽃게사게 | AX4: =MAX('1'!$AI$8:$AI$35,'1'!$AI$39:$AI$62,'1'!$AI$66:$AI$75) -> 630000 | AY4: ='1'!$C$39 -> 3 | AZ4: ='1'!$B$41 -> 이웅 | BA4: ='1'!$B$42 -> 배기성 | BB4: ='1'!$B$43 -> 문효영 | BC4: ='1'!$B$44 -> 0 | BD4: ='1'!$B$45 -> 0 | BE4: ='1'!$B$46 -> 0 | BF4: ='1'!$C$41 -> 0 | BG4: ='1'!$C$42 -> 0 | BH4: ='1'!$C$43 -> 0 | BI4: ='1'!$C$44 -> 0 | BJ4: ='1'!$C$45 -> 0 | BK4: ='1'!$C$46 -> 0 | BL4: ='1'!$AH$4 -> 24245 | BM4: 날짜 | BN4: 매입금액 | BP4: 날짜 | BQ4: 매입금액
B5: 1 | C5: 이웅 | D5: =COUNTIF('1'!$B$41:$C$46,$C$5) -> 1 | E5: =COUNTIF('2'!$B$41:$C$46,$C$5) -> 1 | F5: =COUNTIF('3'!$B$41:$C$46,$C$5) -> 0 | G5: =COUNTIF('4'!$B$41:$C$46,$C$5) -> 1 | H5: =COUNTIF('5'!$B$41:$C$46,$C$5) -> 1 | I5: =COUNTIF('6'!$B$41:$C$46,$C$5) -> 1 | J5: =COUNTIF('7'!$B$41:$C$46,$C$5) -> 1 | K5: =COUNTIF('8'!$B$41:$C$46,$C$5) -> 1 | L5: =COUNTIF('9'!$B$41:$C$46,$C$5) -> 1 | M5: =COUNTIF('10'!$B$41:$C$46,$C$5) -> 0 | N5: =COUNTIF('11'!$B$41:$C$46,$C$5) -> 1 | O5: =COUNTIF('12'!$B$41:$C$46,$C$5) -> 1 | P5: =COUNTIF('13'!$B$41:$C$46,$C$5) -> 1 | Q5: =COUNTIF('14'!$B$41:$C$46,$C$5) -> 1 | R5: =COUNTIF('15'!$B$41:$C$46,$C$5) -> 1 | S5: =COUNTIF('16'!$B$41:$C$46,$C$5) -> 1 | T5: =COUNTIF('17'!$B$41:$C$46,$C$5) -> 0 | U5: =COUNTIF('18'!$B$41:$C$46,$C$5) -> 1 | V5: =COUNTIF('19'!$B$41:$C$46,$C$5) -> 1 | W5: =COUNTIF('20'!$B$41:$C$46,$C$5) -> 1 | X5: =COUNTIF('21'!$B$41:$C$46,$C$5) -> 1 | Y5: =COUNTIF('22'!$B$41:$C$46,$C$5) -> 1 | Z5: =COUNTIF('23'!$B$41:$C$46,$C$5) -> 1 | AA5: =COUNTIF('24'!$B$41:$C$46,$C$5) -> 0 | AB5: =COUNTIF('25'!$B$41:$C$46,$C$5) -> 1 | AC5: =COUNTIF('26'!$B$41:$C$46,$C$5) -> 1 | AD5: =COUNTIF('27'!$B$41:$C$46,$C$5) -> 0 | AE5: =COUNTIF('28'!$B$41:$C$46,$C$5) -> 0 | AF5: =COUNTIF('29'!$B$41:$C$46,$C$5) -> 0 | AG5: =COUNTIF('30'!$B$41:$C$46,$C$5) -> 0 | AH5: =COUNTIF('31'!$B$41:$C$46,$C$5) -> 0 | AI5: =SUM(D5:AH5) -> 22 | AK5: 이웅 | AM5: 2 | AN5: ='2'!$G$2 -> 현대 | AO5: ='2'!$C$5 -> 4217000 | AP5: ='2'!$C$22 -> 1328000 | AQ5: ='2'!$C$23 -> 2804000 | AR5: ='2'!$C$15 -> 1173130 | AS5: ='2'!$C$17 -> 0.27819066 | AT5: ='2'!$C$36 -> 85000 | AU5: ='2'!$C$19 -> 1088130 | AV5: =IFERROR(AO5/AY5,0) -> 1405666.7 | AW5: =VLOOKUP(AX5,IF({1,0},'2'!$AI$8:'2'!$AI$75,'2'!$AD$8:$AD$75),2,0) -> 꽃게사게B | AX5: =MAX('2'!$AI$8:$AI$35,'2'!$AI$39:$AI$62,'2'!$AI$66:$AI$75) -> 420000 | AY5: ='2'!$C$39 -> 3 | AZ5: ='2'!$B$41 -> 이웅 | BA5: ='2'!$B$42 -> 배기성 | BB5: ='2'!$B$43 -> 문효영 | BC5: ='2'!$B$44 -> 0 | BD5: ='2'!$B$45 -> 0 | BE5: ='2'!$B$46 -> 0 | BF5: ='2'!$C$41 -> 0 | BG5: ='2'!$C$42 -> 0 | BH5: ='2'!$C$43 -> 0 | BI5: ='2'!$C$44 -> 0 | BJ5: ='2'!$C$45 -> 0 | BK5: ='2'!$C$46 -> 0 | BL5: ='2'!$AH$4 -> 23105 | BM5: 1 | BN5: ='1'!C7 -> 3066500 | BP5: 17 | BQ5: ='17'!C7 -> 0
B6: 2 | C6: 배기성 | D6: =COUNTIF('1'!$B$41:$C$46,$C$6) -> 1 | E6: =COUNTIF('2'!$B$41:$C$46,$C$6) -> 1 | F6: =COUNTIF('3'!$B$41:$C$46,$C$6) -> 0 | G6: =COUNTIF('4'!$B$41:$C$46,$C$6) -> 1 | H6: =COUNTIF('5'!$B$41:$C$46,$C$6) -> 1 | I6: =COUNTIF('6'!$B$41:$C$46,$C$6) -> 1 | J6: =COUNTIF('7'!$B$41:$C$46,$C$6) -> 1 | K6: =COUNTIF('8'!$B$41:$C$46,$C$6) -> 1 | L6: =COUNTIF('9'!$B$41:$C$46,$C$6) -> 1 | M6: =COUNTIF('10'!$B$41:$C$46,$C$6) -> 0 | N6: =COUNTIF('11'!$B$41:$C$46,$C$6) -> 1 | O6: =COUNTIF('12'!$B$41:$C$46,$C$6) -> 1 | P6: =COUNTIF('13'!$B$41:$C$46,$C$6) -> 1 | Q6: =COUNTIF('14'!$B$41:$C$46,$C$6) -> 1 | R6: =COUNTIF('15'!$B$41:$C$46,$C$6) -> 1 | S6: =COUNTIF('16'!$B$41:$C$46,$C$6) -> 1 | T6: =COUNTIF('17'!$B$41:$C$46,$C$6) -> 0 | U6: =COUNTIF('18'!$B$41:$C$46,$C$6) -> 1 | V6: =COUNTIF('19'!$B$41:$C$46,$C$6) -> 1 | W6: =COUNTIF('20'!$B$41:$C$46,$C$6) -> 1 | X6: =COUNTIF('21'!$B$41:$C$46,$C$6) -> 1 | Y6: =COUNTIF('22'!$B$41:$C$46,$C$6) -> 1 | Z6: =COUNTIF('23'!$B$41:$C$46,$C$6) -> 1 | AA6: =COUNTIF('24'!$B$41:$C$46,$C$6) -> 0 | AB6: =COUNTIF('25'!$B$41:$C$46,$C$6) -> 1 | AC6: =COUNTIF('26'!$B$41:$C$46,$C$6) -> 1 | AD6: =COUNTIF('27'!$B$41:$C$46,$C$6) -> 0 | AE6: =COUNTIF('28'!$B$41:$C$46,$C$6) -> 0 | AF6: =COUNTIF('29'!$B$41:$C$46,$C$6) -> 0 | AG6: =COUNTIF('30'!$B$41:$C$46,$C$6) -> 0 | AH6: =COUNTIF('31'!$B$41:$C$46,$C$6) -> 0 | AI6: =SUM(D6:AH6) -> 22 | AK6: 배기성 | AM6: 3 | AN6: ='3'!$G$2 -> 현대 | AO6: ='3'!$C$5 -> 0 | AP6: ='3'!$C$22 -> 0 | AQ6: ='3'!$C$23 -> 0 | AR6: ='3'!$C$15 -> 0 | AS6: ='3'!$C$17 -> 0 | AT6: ='3'!$C$36 -> 0 | AU6: ='3'!$C$19 -> 0 | AV6: =IFERROR(AO6/AY6,0) -> 0 | AW6: =VLOOKUP(AX6,IF({1,0},'3'!$AI$8:'3'!$AI$75,'3'!$AD$8:$AD$75),2,0) -> 냉)포크오징어M2 | AX6: =MAX('3'!$AI$8:$AI$35,'3'!$AI$39:$AI$62,'3'!$AI$66:$AI$75) -> 0 | AY6: ='3'!$C$39 -> 0 | AZ6: ='3'!$B$41 -> 0 | BA6: ='3'!$B$42 -> 0 | BB6: ='3'!$B$43 -> 0 | BC6: ='3'!$B$44 -> 0 | BD6: ='3'!$B$45 -> 0 | BE6: ='3'!$B$46 -> 0 | BF6: ='3'!$C$41 -> 0 | BG6: ='3'!$C$42 -> 0 | BH6: ='3'!$C$43 -> 0 | BI6: ='3'!$C$44 -> 0 | BJ6: ='3'!$C$45 -> 0 | BK6: ='3'!$C$46 -> 0 | BL6: ='3'!$AH$4 -> 0 | BM6: 2 | BN6: ='2'!C7 -> 3293000 | BP6: 18 | BQ6: ='18'!C7 -> 1746000
B7: 3 | C7: 문효영 | D7: =COUNTIF('1'!$B$41:$C$46,$C$7) -> 1 | E7: =COUNTIF('2'!$B$41:$C$46,$C$7) -> 1 | F7: =COUNTIF('3'!$B$41:$C$46,$C$7) -> 0 | G7: =COUNTIF('4'!$B$41:$C$46,$C$7) -> 1 | H7: =COUNTIF('5'!$B$41:$C$46,$C$7) -> 1 | I7: =COUNTIF('6'!$B$41:$C$46,$C$7) -> 1 | J7: =COUNTIF('7'!$B$41:$C$46,$C$7) -> 1 | K7: =COUNTIF('8'!$B$41:$C$46,$C$7) -> 1 | L7: =COUNTIF('9'!$B$41:$C$46,$C$7) -> 1 | M7: =COUNTIF('10'!$B$41:$C$46,$C$7) -> 0 | N7: =COUNTIF('11'!$B$41:$C$46,$C$7) -> 1 | O7: =COUNTIF('12'!$B$41:$C$46,$C$7) -> 1 | P7: =COUNTIF('13'!$B$41:$C$46,$C$7) -> 1 | Q7: =COUNTIF('14'!$B$41:$C$46,$C$7) -> 1 | R7: =COUNTIF('15'!$B$41:$C$46,$C$7) -> 1 | S7: =COUNTIF('16'!$B$41:$C$46,$C$7) -> 1 | T7: =COUNTIF('17'!$B$41:$C$46,$C$7) -> 0 | U7: =COUNTIF('18'!$B$41:$C$46,$C$7) -> 1 | V7: =COUNTIF('19'!$B$41:$C$46,$C$7) -> 1 | W7: =COUNTIF('20'!$B$41:$C$46,$C$7) -> 1 | X7: =COUNTIF('21'!$B$41:$C$46,$C$7) -> 1 | Y7: =COUNTIF('22'!$B$41:$C$46,$C$7) -> 1 | Z7: =COUNTIF('23'!$B$41:$C$46,$C$7) -> 1 | AA7: =COUNTIF('24'!$B$41:$C$46,$C$7) -> 0 | AB7: =COUNTIF('25'!$B$41:$C$46,$C$7) -> 1 | AC7: =COUNTIF('26'!$B$41:$C$46,$C$7) -> 0 | AD7: =COUNTIF('27'!$B$41:$C$46,$C$7) -> 0 | AE7: =COUNTIF('28'!$B$41:$C$46,$C$7) -> 0 | AF7: =COUNTIF('29'!$B$41:$C$46,$C$7) -> 0 | AG7: =COUNTIF('30'!$B$41:$C$46,$C$7) -> 0 | AH7: =COUNTIF('31'!$B$41:$C$46,$C$7) -> 0 | AI7: =SUM(D7:AH7) -> 21 | AK7: 문효영 | AM7: 4 | AN7: ='4'!$G$2 -> 현대 | AO7: ='4'!$C$5 -> 3416000 | AP7: ='4'!$C$22 -> 1027000 | AQ7: ='4'!$C$23 -> 2304000 | AR7: ='4'!$C$15 -> 966280 | AS7: ='4'!$C$17 -> 0.28286885 | AT7: ='4'!$C$36 -> 85000 | AU7: ='4'!$C$19 -> 881280 | AV7: =IFERROR(AO7/AY7,0) -> 1138666.7 | AW7: =VLOOKUP(AX7,IF({1,0},'4'!$AI$8:'4'!$AI$75,'4'!$AD$8:$AD$75),2,0) -> 냉)참조기40-42 | AX7: =MAX('4'!$AI$8:$AI$35,'4'!$AI$39:$AI$62,'4'!$AI$66:$AI$75) -> 504400 | AY7: ='4'!$C$39 -> 3 | AZ7: ='4'!$B$41 -> 이웅 | BA7: ='4'!$B$42 -> 배기성 | BB7: ='4'!$B$43 -> 문효영 | BC7: ='4'!$B$44 -> 0 | BD7: ='4'!$B$45 -> 0 | BE7: ='4'!$B$46 -> 0 | BF7: ='4'!$C$41 -> 0 | BG7: ='4'!$C$42 -> 0 | BH7: ='4'!$C$43 -> 0 | BI7: ='4'!$C$44 -> 0 | BJ7: ='4'!$C$45 -> 0 | BK7: ='4'!$C$46 -> 0 | BL7: ='4'!$AH$4 -> 157400 | BM7: 3 | BN7: ='3'!C7 -> 0 | BP7: 19 | BQ7: ='19'!C7 -> 2370500
B8: 4 | D8: =COUNTIF('1'!$B$41:$C$46,$C$8) -> 0 | E8: =COUNTIF('2'!$B$41:$C$46,$C$8) -> 0 | F8: =COUNTIF('3'!$B$41:$C$46,$C$8) -> 0 | G8: =COUNTIF('4'!$B$41:$C$46,$C$8) -> 0 | H8: =COUNTIF('5'!$B$41:$C$46,$C$8) -> 0 | I8: =COUNTIF('6'!$B$41:$C$46,$C$8) -> 0 | J8: =COUNTIF('7'!$B$41:$C$46,$C$8) -> 0 | K8: =COUNTIF('8'!$B$41:$C$46,$C$8) -> 0 | L8: =COUNTIF('9'!$B$41:$C$46,$C$8) -> 0 | M8: =COUNTIF('10'!$B$41:$C$46,$C$8) -> 0 | N8: =COUNTIF('11'!$B$41:$C$46,$C$8) -> 0 | O8: =COUNTIF('12'!$B$41:$C$46,$C$8) -> 0 | P8: =COUNTIF('13'!$B$41:$C$46,$C$8) -> 0 | Q8: =COUNTIF('14'!$B$41:$C$46,$C$8) -> 0 | R8: =COUNTIF('15'!$B$41:$C$46,$C$8) -> 0 | S8: =COUNTIF('16'!$B$41:$C$46,$C$8) -> 0 | T8: =COUNTIF('17'!$B$41:$C$46,$C$8) -> 0 | U8: =COUNTIF('18'!$B$41:$C$46,$C$8) -> 0 | V8: =COUNTIF('19'!$B$41:$C$46,$C$8) -> 0 | W8: =COUNTIF('20'!$B$41:$C$46,$C$8) -> 0 | X8: =COUNTIF('21'!$B$41:$C$46,$C$8) -> 0 | Y8: =COUNTIF('22'!$B$41:$C$46,$C$8) -> 0 | Z8: =COUNTIF('23'!$B$41:$C$46,$C$8) -> 0 | AA8: =COUNTIF('24'!$B$41:$C$46,$C$8) -> 0 | AB8: =COUNTIF('25'!$B$41:$C$46,$C$8) -> 0 | AC8: =COUNTIF('26'!$B$41:$C$46,$C$8) -> 0 | AD8: =COUNTIF('27'!$B$41:$C$46,$C$8) -> 0 | AE8: =COUNTIF('28'!$B$41:$C$46,$C$8) -> 0 | AF8: =COUNTIF('29'!$B$41:$C$46,$C$8) -> 0 | AG8: =COUNTIF('30'!$B$41:$C$46,$C$8) -> 0 | AH8: =COUNTIF('31'!$B$41:$C$46,$C$8) -> 0 | AI8: =SUM(D8:AH8) -> 0 | AM8: 5 | AN8: ='5'!$G$2 -> 현대 | AO8: ='5'!$C$5 -> 3125000 | AP8: ='5'!$C$22 -> 703000 | AQ8: ='5'!$C$23 -> 2262000 | AR8: ='5'!$C$15 -> 684500 | AS8: ='5'!$C$17 -> 0.21904 | AT8: ='5'!$C$36 -> 160000 | AU8: ='5'!$C$19 -> 524500 | AV8: =IFERROR(AO8/AY8,0) -> 1041666.7 | AW8: =VLOOKUP(AX8,IF({1,0},'5'!$AI$8:'5'!$AI$75,'5'!$AD$8:$AD$75),2,0) -> 꽃게사게 | AX8: =MAX('5'!$AI$8:$AI$35,'5'!$AI$39:$AI$62,'5'!$AI$66:$AI$75) -> 345000 | AY8: ='5'!$C$39 -> 3 | AZ8: ='5'!$B$41 -> 이웅 | BA8: ='5'!$B$42 -> 배기성 | BB8: ='5'!$B$43 -> 문효영 | BC8: ='5'!$B$44 -> 0 | BD8: ='5'!$B$45 -> 0 | BE8: ='5'!$B$46 -> 0 | BF8: ='5'!$C$41 -> 0 | BG8: ='5'!$C$42 -> 0 | BH8: ='5'!$C$43 -> 0 | BI8: ='5'!$C$44 -> 0 | BJ8: ='5'!$C$45 -> 0 | BK8: ='5'!$C$46 -> 0 | BL8: ='5'!$AH$4 -> -50652 | BM8: 4 | BN8: ='4'!C7 -> 1663000 | BP8: 20 | BQ8: ='20'!C7 -> 1790000
B9: 5 | D9: =COUNTIF('1'!$B$41:$C$46,$C$9) -> 0 | E9: =COUNTIF('2'!$B$41:$C$46,$C$9) -> 0 | F9: =COUNTIF('3'!$B$41:$C$46,$C$9) -> 0 | G9: =COUNTIF('4'!$B$41:$C$46,$C$9) -> 0 | H9: =COUNTIF('5'!$B$41:$C$46,$C$9) -> 0 | I9: =COUNTIF('6'!$B$41:$C$46,$C$9) -> 0 | J9: =COUNTIF('7'!$B$41:$C$46,$C$9) -> 0 | K9: =COUNTIF('8'!$B$41:$C$46,$C$9) -> 0 | L9: =COUNTIF('9'!$B$41:$C$46,$C$9) -> 0 | M9: =COUNTIF('10'!$B$41:$C$46,$C$9) -> 0 | N9: =COUNTIF('11'!$B$41:$C$46,$C$9) -> 0 | O9: =COUNTIF('12'!$B$41:$C$46,$C$9) -> 0 | P9: =COUNTIF('13'!$B$41:$C$46,$C$9) -> 0 | Q9: =COUNTIF('14'!$B$41:$C$46,$C$9) -> 0 | R9: =COUNTIF('15'!$B$41:$C$46,$C$9) -> 0 | S9: =COUNTIF('16'!$B$41:$C$46,$C$9) -> 0 | T9: =COUNTIF('17'!$B$41:$C$46,$C$9) -> 0 | U9: =COUNTIF('18'!$B$41:$C$46,$C$9) -> 0 | V9: =COUNTIF('19'!$B$41:$C$46,$C$9) -> 0 | W9: =COUNTIF('20'!$B$41:$C$46,$C$9) -> 0 | X9: =COUNTIF('21'!$B$41:$C$46,$C$9) -> 0 | Y9: =COUNTIF('22'!$B$41:$C$46,$C$9) -> 0 | Z9: =COUNTIF('23'!$B$41:$C$46,$C$9) -> 0 | AA9: =COUNTIF('24'!$B$41:$C$46,$C$9) -> 0 | AB9: =COUNTIF('25'!$B$41:$C$46,$C$9) -> 0 | AC9: =COUNTIF('26'!$B$41:$C$46,$C$9) -> 0 | AD9: =COUNTIF('27'!$B$41:$C$46,$C$9) -> 0 | AE9: =COUNTIF('28'!$B$41:$C$46,$C$9) -> 0 | AF9: =COUNTIF('29'!$B$41:$C$46,$C$9) -> 0 | AG9: =COUNTIF('30'!$B$41:$C$46,$C$9) -> 0 | AH9: =COUNTIF('31'!$B$41:$C$46,$C$9) -> 0 | AI9: =SUM(D9:AH9) -> 0 | AM9: 6 | AN9: ='6'!$G$2 -> 현대 | AO9: ='6'!$C$5 -> 3258000 | AP9: ='6'!$C$22 -> 1317000 | AQ9: ='6'!$C$23 -> 1856000 | AR9: ='6'!$C$15 -> 874400 | AS9: ='6'!$C$17 -> 0.26838551 | AT9: ='6'!$C$36 -> 85000 | AU9: ='6'!$C$19 -> 789400 | AV9: =IFERROR(AO9/AY9,0) -> 1086000 | AW9: =VLOOKUP(AX9,IF({1,0},'6'!$AI$8:'6'!$AI$75,'6'!$AD$8:$AD$75),2,0) -> 꽃게사게 | AX9: =MAX('6'!$AI$8:$AI$35,'6'!$AI$39:$AI$62,'6'!$AI$66:$AI$75) -> 510000 | AY9: ='6'!$C$39 -> 3 | AZ9: ='6'!$B$41 -> 이웅 | BA9: ='6'!$B$42 -> 배기성 | BB9: ='6'!$B$43 -> 문효영 | BC9: ='6'!$B$44 -> 0 | BD9: ='6'!$B$45 -> 0 | BE9: ='6'!$B$46 -> 0 | BF9: ='6'!$C$41 -> 0 | BG9: ='6'!$C$42 -> 0 | BH9: ='6'!$C$43 -> 0 | BI9: ='6'!$C$44 -> 0 | BJ9: ='6'!$C$45 -> 0 | BK9: ='6'!$C$46 -> 0 | BL9: ='6'!$AH$4 -> -3902 | BM9: 5 | BN9: ='5'!C7 -> 2565500 | BP9: 21 | BQ9: ='21'!C7 -> 1022000
B10: 6 | D10: =COUNTIF('1'!$B$41:$C$46,$C$10) -> 0 | E10: =COUNTIF('2'!$B$41:$C$46,$C$10) -> 0 | F10: =COUNTIF('3'!$B$41:$C$46,$C$10) -> 0 | G10: =COUNTIF('4'!$B$41:$C$46,$C$10) -> 0 | H10: =COUNTIF('5'!$B$41:$C$46,$C$10) -> 0 | I10: =COUNTIF('6'!$B$41:$C$46,$C$10) -> 0 | J10: =COUNTIF('7'!$B$41:$C$46,$C$10) -> 0 | K10: =COUNTIF('8'!$B$41:$C$46,$C$10) -> 0 | L10: =COUNTIF('9'!$B$41:$C$46,$C$10) -> 0 | M10: =COUNTIF('10'!$B$41:$C$46,$C$10) -> 0 | N10: =COUNTIF('11'!$B$41:$C$46,$C$10) -> 0 | O10: =COUNTIF('12'!$B$41:$C$46,$C$10) -> 0 | P10: =COUNTIF('13'!$B$41:$C$46,$C$10) -> 0 | Q10: =COUNTIF('14'!$B$41:$C$46,$C$10) -> 0 | R10: =COUNTIF('15'!$B$41:$C$46,$C$10) -> 0 | S10: =COUNTIF('16'!$B$41:$C$46,$C$10) -> 0 | T10: =COUNTIF('17'!$B$41:$C$46,$C$10) -> 0 | U10: =COUNTIF('18'!$B$41:$C$46,$C$10) -> 0 | V10: =COUNTIF('19'!$B$41:$C$46,$C$10) -> 0 | W10: =COUNTIF('20'!$B$41:$C$46,$C$10) -> 0 | X10: =COUNTIF('21'!$B$41:$C$46,$C$10) -> 0 | Y10: =COUNTIF('22'!$B$41:$C$46,$C$10) -> 0 | Z10: =COUNTIF('23'!$B$41:$C$46,$C$10) -> 0 | AA10: =COUNTIF('24'!$B$41:$C$46,$C$10) -> 0 | AB10: =COUNTIF('25'!$B$41:$C$46,$C$10) -> 0 | AC10: =COUNTIF('26'!$B$41:$C$46,$C$10) -> 0 | AD10: =COUNTIF('27'!$B$41:$C$46,$C$10) -> 0 | AE10: =COUNTIF('28'!$B$41:$C$46,$C$10) -> 0 | AF10: =COUNTIF('29'!$B$41:$C$46,$C$10) -> 0 | AG10: =COUNTIF('30'!$B$41:$C$46,$C$10) -> 0 | AH10: =COUNTIF('31'!$B$41:$C$46,$C$10) -> 0 | AI10: =SUM(D10:AH10) -> 0 | AM10: 7 | AN10: ='7'!$G$2 -> 현대 | AO10: ='7'!$C$5 -> 2796000 | AP10: ='7'!$C$22 -> 1018000 | AQ10: ='7'!$C$23 -> 1693000 | AR10: ='7'!$C$15 -> 700860 | AS10: ='7'!$C$17 -> 0.25066524 | AT10: ='7'!$C$36 -> 85000 | AU10: ='7'!$C$19 -> 615860 | AV10: =IFERROR(AO10/AY10,0) -> 932000 | AW10: =VLOOKUP(AX10,IF({1,0},'7'!$AI$8:'7'!$AI$75,'7'!$AD$8:$AD$75),2,0) -> 냉)선동제주갈치31-33 | AX10: =MAX('7'!$AI$8:$AI$35,'7'!$AI$39:$AI$62,'7'!$AI$66:$AI$75) -> 323510 | AY10: ='7'!$C$39 -> 3 | AZ10: ='7'!$B$41 -> 이웅 | BA10: ='7'!$B$42 -> 배기성 | BB10: ='7'!$B$43 -> 문효영 | BC10: ='7'!$B$44 -> 0 | BD10: ='7'!$B$45 -> 0 | BE10: ='7'!$B$46 -> 0 | BF10: ='7'!$C$41 -> 0 | BG10: ='7'!$C$42 -> 0 | BH10: ='7'!$C$43 -> 0 | BI10: ='7'!$C$44 -> 0 | BJ10: ='7'!$C$45 -> 0 | BK10: ='7'!$C$46 -> 0 | BL10: ='7'!$AH$4 -> -37940 | BM10: 6 | BN10: ='6'!C7 -> 2165000 | BP10: 22 | BQ10: ='22'!C7 -> 2245000
B11: 7 | D11: =COUNTIF('1'!$B$41:$C$46,$C$11) -> 0 | E11: =COUNTIF('2'!$B$41:$C$46,$C$11) -> 0 | F11: =COUNTIF('3'!$B$41:$C$46,$C$11) -> 0 | G11: =COUNTIF('4'!$B$41:$C$46,$C$11) -> 0 | H11: =COUNTIF('5'!$B$41:$C$46,$C$11) -> 0 | I11: =COUNTIF('6'!$B$41:$C$46,$C$11) -> 0 | J11: =COUNTIF('7'!$B$41:$C$46,$C$11) -> 0 | K11: =COUNTIF('8'!$B$41:$C$46,$C$11) -> 0 | L11: =COUNTIF('9'!$B$41:$C$46,$C$11) -> 0 | M11: =COUNTIF('10'!$B$41:$C$46,$C$11) -> 0 | N11: =COUNTIF('11'!$B$41:$C$46,$C$11) -> 0 | O11: =COUNTIF('12'!$B$41:$C$46,$C$11) -> 0 | P11: =COUNTIF('13'!$B$41:$C$46,$C$11) -> 0 | Q11: =COUNTIF('14'!$B$41:$C$46,$C$11) -> 0 | R11: =COUNTIF('15'!$B$41:$C$46,$C$11) -> 0 | S11: =COUNTIF('16'!$B$41:$C$46,$C$11) -> 0 | T11: =COUNTIF('17'!$B$41:$C$46,$C$11) -> 0 | U11: =COUNTIF('18'!$B$41:$C$46,$C$11) -> 0 | V11: =COUNTIF('19'!$B$41:$C$46,$C$11) -> 0 | W11: =COUNTIF('20'!$B$41:$C$46,$C$11) -> 0 | X11: =COUNTIF('21'!$B$41:$C$46,$C$11) -> 0 | Y11: =COUNTIF('22'!$B$41:$C$46,$C$11) -> 0 | Z11: =COUNTIF('23'!$B$41:$C$46,$C$11) -> 0 | AA11: =COUNTIF('24'!$B$41:$C$46,$C$11) -> 0 | AB11: =COUNTIF('25'!$B$41:$C$46,$C$11) -> 0 | AC11: =COUNTIF('26'!$B$41:$C$46,$C$11) -> 0 | AD11: =COUNTIF('27'!$B$41:$C$46,$C$11) -> 0 | AE11: =COUNTIF('28'!$B$41:$C$46,$C$11) -> 0 | AF11: =COUNTIF('29'!$B$41:$C$46,$C$11) -> 0 | AG11: =COUNTIF('30'!$B$41:$C$46,$C$11) -> 0 | AH11: =COUNTIF('31'!$B$41:$C$46,$C$11) -> 0 | AI11: =SUM(D11:AH11) -> 0 | AM11: 8 | AN11: ='8'!$G$2 -> 현대 | AO11: ='8'!$C$5 -> 4012000 | AP11: ='8'!$C$22 -> 1328000 | AQ11: ='8'!$C$23 -> 2599000 | AR11: ='8'!$C$15 -> 1157775 | AS11: ='8'!$C$17 -> 0.28857802 | AT11: ='8'!$C$36 -> 85000 | AU11: ='8'!$C$19 -> 1072775 | AV11: =IFERROR(AO11/AY11,0) -> 1337333.3 | AW11: =VLOOKUP(AX11,IF({1,0},'8'!$AI$8:'8'!$AI$75,'8'!$AD$8:$AD$75),2,0) -> 꽃게사게 | AX11: =MAX('8'!$AI$8:$AI$35,'8'!$AI$39:$AI$62,'8'!$AI$66:$AI$75) -> 480000 | AY11: ='8'!$C$39 -> 3 | AZ11: ='8'!$B$41 -> 이웅 | BA11: ='8'!$B$42 -> 배기성 | BB11: ='8'!$B$43 -> 문효영 | BC11: ='8'!$B$44 -> 0 | BD11: ='8'!$B$45 -> 0 | BE11: ='8'!$B$46 -> 0 | BF11: ='8'!$C$41 -> 0 | BG11: ='8'!$C$42 -> 0 | BH11: ='8'!$C$43 -> 0 | BI11: ='8'!$C$44 -> 0 | BJ11: ='8'!$C$45 -> 0 | BK11: ='8'!$C$46 -> 0 | BL11: ='8'!$AH$4 -> 64942 | BM11: 7 | BN11: ='7'!C7 -> 2858000 | BP11: 23 | BQ11: ='23'!C7 -> 2581000
B12: 8 | D12: =COUNTIF('1'!$B$41:$C$46,$C$12) -> 0 | E12: =COUNTIF('2'!$B$41:$C$46,$C$12) -> 0 | F12: =COUNTIF('3'!$B$41:$C$46,$C$12) -> 0 | G12: =COUNTIF('4'!$B$41:$C$46,$C$12) -> 0 | H12: =COUNTIF('5'!$B$41:$C$46,$C$12) -> 0 | I12: =COUNTIF('6'!$B$41:$C$46,$C$12) -> 0 | J12: =COUNTIF('7'!$B$41:$C$46,$C$12) -> 0 | K12: =COUNTIF('8'!$B$41:$C$46,$C$12) -> 0 | L12: =COUNTIF('9'!$B$41:$C$46,$C$12) -> 0 | M12: =COUNTIF('10'!$B$41:$C$46,$C$12) -> 0 | N12: =COUNTIF('11'!$B$41:$C$46,$C$12) -> 0 | O12: =COUNTIF('12'!$B$41:$C$46,$C$12) -> 0 | P12: =COUNTIF('13'!$B$41:$C$46,$C$12) -> 0 | Q12: =COUNTIF('14'!$B$41:$C$46,$C$12) -> 0 | R12: =COUNTIF('15'!$B$41:$C$46,$C$12) -> 0 | S12: =COUNTIF('16'!$B$41:$C$46,$C$12) -> 0 | T12: =COUNTIF('17'!$B$41:$C$46,$C$12) -> 0 | U12: =COUNTIF('18'!$B$41:$C$46,$C$12) -> 0 | V12: =COUNTIF('19'!$B$41:$C$46,$C$12) -> 0 | W12: =COUNTIF('20'!$B$41:$C$46,$C$12) -> 0 | X12: =COUNTIF('21'!$B$41:$C$46,$C$12) -> 0 | Y12: =COUNTIF('22'!$B$41:$C$46,$C$12) -> 0 | Z12: =COUNTIF('23'!$B$41:$C$46,$C$12) -> 0 | AA12: =COUNTIF('24'!$B$41:$C$46,$C$12) -> 0 | AB12: =COUNTIF('25'!$B$41:$C$46,$C$12) -> 0 | AC12: =COUNTIF('26'!$B$41:$C$46,$C$12) -> 0 | AD12: =COUNTIF('27'!$B$41:$C$46,$C$12) -> 0 | AE12: =COUNTIF('28'!$B$41:$C$46,$C$12) -> 0 | AF12: =COUNTIF('29'!$B$41:$C$46,$C$12) -> 0 | AG12: =COUNTIF('30'!$B$41:$C$46,$C$12) -> 0 | AH12: =COUNTIF('31'!$B$41:$C$46,$C$12) -> 0 | AI12: =SUM(D12:AH12) -> 0 | AM12: 9 | AN12: ='9'!$G$2 -> 현대 | AO12: ='9'!$C$5 -> 3282000 | AP12: ='9'!$C$22 -> 949000 | AQ12: ='9'!$C$23 -> 2248000 | AR12: ='9'!$C$15 -> 937270 | AS12: ='9'!$C$17 -> 0.28557892 | AT12: ='9'!$C$36 -> 85000 | AU12: ='9'!$C$19 -> 852270 | AV12: =IFERROR(AO12/AY12,0) -> 1094000 | AW12: =VLOOKUP(AX12,IF({1,0},'9'!$AI$8:'9'!$AI$75,'9'!$AD$8:$AD$75),2,0) -> 활문어 | AX12: =MAX('9'!$AI$8:$AI$35,'9'!$AI$39:$AI$62,'9'!$AI$66:$AI$75) -> 405000 | AY12: ='9'!$C$39 -> 3 | AZ12: ='9'!$B$41 -> 이웅 | BA12: ='9'!$B$42 -> 배기성 | BB12: ='9'!$B$43 -> 문효영 | BC12: ='9'!$B$44 -> 0 | BD12: ='9'!$B$45 -> 0 | BE12: ='9'!$B$46 -> 0 | BF12: ='9'!$C$41 -> 0 | BG12: ='9'!$C$42 -> 0 | BH12: ='9'!$C$43 -> 0 | BI12: ='9'!$C$44 -> 0 | BJ12: ='9'!$C$45 -> 0 | BK12: ='9'!$C$46 -> 0 | BL12: ='9'!$AH$4 -> 45060 | BM12: 8 | BN12: ='8'!C7 -> 2042000 | BP12: 24 | BQ12: ='24'!C7 -> 0
B13: 9 | D13: =COUNTIF('1'!$B$41:$C$46,$C$13) -> 0 | E13: =COUNTIF('2'!$B$41:$C$46,$C$13) -> 0 | F13: =COUNTIF('3'!$B$41:$C$46,$C$13) -> 0 | G13: =COUNTIF('4'!$B$41:$C$46,$C$13) -> 0 | H13: =COUNTIF('5'!$B$41:$C$46,$C$13) -> 0 | I13: =COUNTIF('6'!$B$41:$C$46,$C$13) -> 0 | J13: =COUNTIF('7'!$B$41:$C$46,$C$13) -> 0 | K13: =COUNTIF('8'!$B$41:$C$46,$C$13) -> 0 | L13: =COUNTIF('9'!$B$41:$C$46,$C$13) -> 0 | M13: =COUNTIF('10'!$B$41:$C$46,$C$13) -> 0 | N13: =COUNTIF('11'!$B$41:$C$46,$C$13) -> 0 | O13: =COUNTIF('12'!$B$41:$C$46,$C$13) -> 0 | P13: =COUNTIF('13'!$B$41:$C$46,$C$13) -> 0 | Q13: =COUNTIF('14'!$B$41:$C$46,$C$13) -> 0 | R13: =COUNTIF('15'!$B$41:$C$46,$C$13) -> 0 | S13: =COUNTIF('16'!$B$41:$C$46,$C$13) -> 0 | T13: =COUNTIF('17'!$B$41:$C$46,$C$13) -> 0 | U13: =COUNTIF('18'!$B$41:$C$46,$C$13) -> 0 | V13: =COUNTIF('19'!$B$41:$C$46,$C$13) -> 0 | W13: =COUNTIF('20'!$B$41:$C$46,$C$13) -> 0 | X13: =COUNTIF('21'!$B$41:$C$46,$C$13) -> 0 | Y13: =COUNTIF('22'!$B$41:$C$46,$C$13) -> 0 | Z13: =COUNTIF('23'!$B$41:$C$46,$C$13) -> 0 | AA13: =COUNTIF('24'!$B$41:$C$46,$C$13) -> 0 | AB13: =COUNTIF('25'!$B$41:$C$46,$C$13) -> 0 | AC13: =COUNTIF('26'!$B$41:$C$46,$C$13) -> 0 | AD13: =COUNTIF('27'!$B$41:$C$46,$C$13) -> 0 | AE13: =COUNTIF('28'!$B$41:$C$46,$C$13) -> 0 | AF13: =COUNTIF('29'!$B$41:$C$46,$C$13) -> 0 | AG13: =COUNTIF('30'!$B$41:$C$46,$C$13) -> 0 | AH13: =COUNTIF('31'!$B$41:$C$46,$C$13) -> 0 | AI13: =SUM(D13:AH13) -> 0 | AM13: 10 | AN13: ='10'!$G$2 -> 현대 | AO13: ='10'!$C$5 -> 0 | AP13: ='10'!$C$22 -> 0 | AQ13: ='10'!$C$23 -> 0 | AR13: ='10'!$C$15 -> 0 | AS13: ='10'!$C$17 -> 0 | AT13: ='10'!$C$36 -> 0 | AU13: ='10'!$C$19 -> 0 | AV13: =IFERROR(AO13/AY13,0) -> 0 | AW13: =VLOOKUP(AX13,IF({1,0},'10'!$AI$8:'10'!$AI$75,'10'!$AD$8:$AD$75),2,0) -> 냉)포크오징어M2A | AX13: =MAX('10'!$AI$8:$AI$35,'10'!$AI$39:$AI$62,'10'!$AI$66:$AI$75) -> 0 | AY13: ='10'!$C$39 -> 0 | AZ13: ='10'!$B$41 -> 0 | BA13: ='10'!$B$42 -> 0 | BB13: ='10'!$B$43 -> 0 | BC13: ='10'!$B$44 -> 0 | BD13: ='10'!$B$45 -> 0 | BE13: ='10'!$B$46 -> 0 | BF13: ='10'!$C$41 -> 0 | BG13: ='10'!$C$42 -> 0 | BH13: ='10'!$C$43 -> 0 | BI13: ='10'!$C$44 -> 0 | BJ13: ='10'!$C$45 -> 0 | BK13: ='10'!$C$46 -> 0 | BL13: ='10'!$AH$4 -> 0 | BM13: 9 | BN13: ='9'!C7 -> 2713000 | BP13: 25 | BQ13: ='25'!C7 -> 2290000
B14: 10 | D14: =COUNTIF('1'!$B$41:$C$46,$C$14) -> 0 | E14: =COUNTIF('2'!$B$41:$C$46,$C$14) -> 0 | F14: =COUNTIF('3'!$B$41:$C$46,$C$14) -> 0 | G14: =COUNTIF('4'!$B$41:$C$46,$C$14) -> 0 | H14: =COUNTIF('5'!$B$41:$C$46,$C$14) -> 0 | I14: =COUNTIF('6'!$B$41:$C$46,$C$14) -> 0 | J14: =COUNTIF('7'!$B$41:$C$46,$C$14) -> 0 | K14: =COUNTIF('8'!$B$41:$C$46,$C$14) -> 0 | L14: =COUNTIF('9'!$B$41:$C$46,$C$14) -> 0 | M14: =COUNTIF('10'!$B$41:$C$46,$C$14) -> 0 | N14: =COUNTIF('11'!$B$41:$C$46,$C$14) -> 0 | O14: =COUNTIF('12'!$B$41:$C$46,$C$14) -> 0 | P14: =COUNTIF('13'!$B$41:$C$46,$C$14) -> 0 | Q14: =COUNTIF('14'!$B$41:$C$46,$C$14) -> 0 | R14: =COUNTIF('15'!$B$41:$C$46,$C$14) -> 0 | S14: =COUNTIF('16'!$B$41:$C$46,$C$14) -> 0 | T14: =COUNTIF('17'!$B$41:$C$46,$C$14) -> 0 | U14: =COUNTIF('18'!$B$41:$C$46,$C$14) -> 0 | V14: =COUNTIF('19'!$B$41:$C$46,$C$14) -> 0 | W14: =COUNTIF('20'!$B$41:$C$46,$C$14) -> 0 | X14: =COUNTIF('21'!$B$41:$C$46,$C$14) -> 0 | Y14: =COUNTIF('22'!$B$41:$C$46,$C$14) -> 0 | Z14: =COUNTIF('23'!$B$41:$C$46,$C$14) -> 0 | AA14: =COUNTIF('24'!$B$41:$C$46,$C$14) -> 0 | AB14: =COUNTIF('25'!$B$41:$C$46,$C$14) -> 0 | AC14: =COUNTIF('26'!$B$41:$C$46,$C$14) -> 0 | AD14: =COUNTIF('27'!$B$41:$C$46,$C$14) -> 0 | AE14: =COUNTIF('28'!$B$41:$C$46,$C$14) -> 0 | AF14: =COUNTIF('29'!$B$41:$C$46,$C$14) -> 0 | AG14: =COUNTIF('30'!$B$41:$C$46,$C$14) -> 0 | AH14: =COUNTIF('31'!$B$41:$C$46,$C$14) -> 0 | AI14: =SUM(D14:AH14) -> 0 | AM14: 11 | AN14: ='11'!$G$2 -> 현대 | AO14: ='11'!$C$5 -> 3566000 | AP14: ='11'!$C$22 -> 1098000 | AQ14: ='11'!$C$23 -> 2280000 | AR14: ='11'!$C$15 -> 1005280 | AS14: ='11'!$C$17 -> 0.2819069 | AT14: ='11'!$C$36 -> 188000 | AU14: ='11'!$C$19 -> 817280 | AV14: =IFERROR(AO14/AY14,0) -> 1188666.7 | AW14: =VLOOKUP(AX14,IF({1,0},'11'!$AI$8:'11'!$AI$75,'11'!$AD$8:$AD$75),2,0) -> 꽃게사게 | AX14: =MAX('11'!$AI$8:$AI$35,'11'!$AI$39:$AI$62,'11'!$AI$66:$AI$75) -> 494400 | AY14: ='11'!$C$39 -> 3 | AZ14: ='11'!$B$41 -> 이웅 | BA14: ='11'!$B$42 -> 배기성 | BB14: ='11'!$B$43 -> 문효영 | BC14: ='11'!$B$44 -> 0 | BD14: ='11'!$B$45 -> 0 | BE14: ='11'!$B$46 -> 0 | BF14: ='11'!$C$41 -> 0 | BG14: ='11'!$C$42 -> 0 | BH14: ='11'!$C$43 -> 0 | BI14: ='11'!$C$44 -> 0 | BJ14: ='11'!$C$45 -> 0 | BK14: ='11'!$C$46 -> 0 | BL14: ='11'!$AH$4 -> 57330 | BM14: 10 | BN14: ='10'!C7 -> 0 | BP14: 26 | BQ14: ='26'!C7 -> 2921000
B15: 11 | D15: =COUNTIF('1'!$B$41:$C$46,$C$15) -> 0 | E15: =COUNTIF('2'!$B$41:$C$46,$C$15) -> 0 | F15: =COUNTIF('3'!$B$41:$C$46,$C$15) -> 0 | G15: =COUNTIF('4'!$B$41:$C$46,$C$15) -> 0 | H15: =COUNTIF('5'!$B$41:$C$46,$C$15) -> 0 | I15: =COUNTIF('6'!$B$41:$C$46,$C$15) -> 0 | J15: =COUNTIF('7'!$B$41:$C$46,$C$15) -> 0 | K15: =COUNTIF('8'!$B$41:$C$46,$C$15) -> 0 | L15: =COUNTIF('9'!$B$41:$C$46,$C$15) -> 0 | M15: =COUNTIF('10'!$B$41:$C$46,$C$15) -> 0 | N15: =COUNTIF('11'!$B$41:$C$46,$C$15) -> 0 | O15: =COUNTIF('12'!$B$41:$C$46,$C$15) -> 0 | P15: =COUNTIF('13'!$B$41:$C$46,$C$15) -> 0 | Q15: =COUNTIF('14'!$B$41:$C$46,$C$15) -> 0 | R15: =COUNTIF('15'!$B$41:$C$46,$C$15) -> 0 | S15: =COUNTIF('16'!$B$41:$C$46,$C$15) -> 0 | T15: =COUNTIF('17'!$B$41:$C$46,$C$15) -> 0 | U15: =COUNTIF('18'!$B$41:$C$46,$C$15) -> 0 | V15: =COUNTIF('19'!$B$41:$C$46,$C$15) -> 0 | W15: =COUNTIF('20'!$B$41:$C$46,$C$15) -> 0 | X15: =COUNTIF('21'!$B$41:$C$46,$C$15) -> 0 | Y15: =COUNTIF('22'!$B$41:$C$46,$C$15) -> 0 | Z15: =COUNTIF('23'!$B$41:$C$46,$C$15) -> 0 | AA15: =COUNTIF('24'!$B$41:$C$46,$C$15) -> 0 | AB15: =COUNTIF('25'!$B$41:$C$46,$C$15) -> 0 | AC15: =COUNTIF('26'!$B$41:$C$46,$C$15) -> 0 | AD15: =COUNTIF('27'!$B$41:$C$46,$C$15) -> 0 | AE15: =COUNTIF('28'!$B$41:$C$46,$C$15) -> 0 | AF15: =COUNTIF('29'!$B$41:$C$46,$C$15) -> 0 | AG15: =COUNTIF('30'!$B$41:$C$46,$C$15) -> 0 | AH15: =COUNTIF('31'!$B$41:$C$46,$C$15) -> 0 | AI15: =SUM(D15:AH15) -> 0 | AM15: 12 | AN15: ='12'!$G$2 -> 현대 | AO15: ='12'!$C$5 -> 3574000 | AP15: ='12'!$C$22 -> 1208000 | AQ15: ='12'!$C$23 -> 2251000 | AR15: ='12'!$C$15 -> 1011220 | AS15: ='12'!$C$17 -> 0.28293788 | AT15: ='12'!$C$36 -> 115000 | AU15: ='12'!$C$19 -> 896220 | AV15: =IFERROR(AO15/AY15,0) -> 1191333.3 | AW15: =VLOOKUP(AX15,IF({1,0},'12'!$AI$8:'12'!$AI$75,'12'!$AD$8:$AD$75),2,0) -> 꽃게사게 | AX15: =MAX('12'!$AI$8:$AI$35,'12'!$AI$39:$AI$62,'12'!$AI$66:$AI$75) -> 520000 | AY15: ='12'!$C$39 -> 3 | AZ15: ='12'!$B$41 -> 이웅 | BA15: ='12'!$B$42 -> 배기성 | BB15: ='12'!$B$43 -> 문효영 | BC15: ='12'!$B$44 -> 0 | BD15: ='12'!$B$45 -> 0 | BE15: ='12'!$B$46 -> 0 | BF15: ='12'!$C$41 -> 0 | BG15: ='12'!$C$42 -> 0 | BH15: ='12'!$C$43 -> 0 | BI15: ='12'!$C$44 -> 0 | BJ15: ='12'!$C$45 -> 0 | BK15: ='12'!$C$46 -> 0 | BL15: ='12'!$AH$4 -> 49490 | BM15: 11 | BN15: ='11'!C7 -> 1687500 | BP15: 27 | BQ15: ='27'!C7 -> 0
B16: 12 | D16: =COUNTIF('1'!$B$41:$C$46,$C$16) -> 0 | E16: =COUNTIF('2'!$B$41:$C$46,$C$16) -> 0 | F16: =COUNTIF('3'!$B$41:$C$46,$C$16) -> 0 | G16: =COUNTIF('4'!$B$41:$C$46,$C$16) -> 0 | H16: =COUNTIF('5'!$B$41:$C$46,$C$16) -> 0 | I16: =COUNTIF('6'!$B$41:$C$46,$C$16) -> 0 | J16: =COUNTIF('7'!$B$41:$C$46,$C$16) -> 0 | K16: =COUNTIF('8'!$B$41:$C$46,$C$16) -> 0 | L16: =COUNTIF('9'!$B$41:$C$46,$C$16) -> 0 | M16: =COUNTIF('10'!$B$41:$C$46,$C$16) -> 0 | N16: =COUNTIF('11'!$B$41:$C$46,$C$16) -> 0 | O16: =COUNTIF('12'!$B$41:$C$46,$C$16) -> 0 | P16: =COUNTIF('13'!$B$41:$C$46,$C$16) -> 0 | Q16: =COUNTIF('14'!$B$41:$C$46,$C$16) -> 0 | R16: =COUNTIF('15'!$B$41:$C$46,$C$16) -> 0 | S16: =COUNTIF('16'!$B$41:$C$46,$C$16) -> 0 | T16: =COUNTIF('17'!$B$41:$C$46,$C$16) -> 0 | U16: =COUNTIF('18'!$B$41:$C$46,$C$16) -> 0 | V16: =COUNTIF('19'!$B$41:$C$46,$C$16) -> 0 | W16: =COUNTIF('20'!$B$41:$C$46,$C$16) -> 0 | X16: =COUNTIF('21'!$B$41:$C$46,$C$16) -> 0 | Y16: =COUNTIF('22'!$B$41:$C$46,$C$16) -> 0 | Z16: =COUNTIF('23'!$B$41:$C$46,$C$16) -> 0 | AA16: =COUNTIF('24'!$B$41:$C$46,$C$16) -> 0 | AB16: =COUNTIF('25'!$B$41:$C$46,$C$16) -> 0 | AC16: =COUNTIF('26'!$B$41:$C$46,$C$16) -> 0 | AD16: =COUNTIF('27'!$B$41:$C$46,$C$16) -> 0 | AE16: =COUNTIF('28'!$B$41:$C$46,$C$16) -> 0 | AF16: =COUNTIF('29'!$B$41:$C$46,$C$16) -> 0 | AG16: =COUNTIF('30'!$B$41:$C$46,$C$16) -> 0 | AH16: =COUNTIF('31'!$B$41:$C$46,$C$16) -> 0 | AI16: =SUM(D16:AH16) -> 0 | AM16: 13 | AN16: ='13'!$G$2 -> 현대 | AO16: ='13'!$C$5 -> 3437000 | AP16: ='13'!$C$22 -> 747000 | AQ16: ='13'!$C$23 -> 2469000 | AR16: ='13'!$C$15 -> 972220 | AS16: ='13'!$C$17 -> 0.28286878 | AT16: ='13'!$C$36 -> 221000 | AU16: ='13'!$C$19 -> 751220 | AV16: =IFERROR(AO16/AY16,0) -> 1145666.7 | AW16: =VLOOKUP(AX16,IF({1,0},'13'!$AI$8:'13'!$AI$75,'13'!$AD$8:$AD$75),2,0) -> 활문어 | AX16: =MAX('13'!$AI$8:$AI$35,'13'!$AI$39:$AI$62,'13'!$AI$66:$AI$75) -> 441000 | AY16: ='13'!$C$39 -> 3 | AZ16: ='13'!$B$41 -> 이웅 | BA16: ='13'!$B$42 -> 배기성 | BB16: ='13'!$B$43 -> 문효영 | BC16: ='13'!$B$44 -> 0 | BD16: ='13'!$B$45 -> 0 | BE16: ='13'!$B$46 -> 0 | BF16: ='13'!$C$41 -> 0 | BG16: ='13'!$C$42 -> 0 | BH16: ='13'!$C$43 -> 0 | BI16: ='13'!$C$44 -> 0 | BJ16: ='13'!$C$45 -> 0 | BK16: ='13'!$C$46 -> 0 | BL16: ='13'!$AH$4 -> 64430 | BM16: 12 | BN16: ='12'!C7 -> 3285500 | BP16: 28 | BQ16: ='28'!C7 -> 0
B17: 13 | D17: =COUNTIF('1'!$B$41:$C$46,$C$17) -> 0 | E17: =COUNTIF('2'!$B$41:$C$46,$C$17) -> 0 | F17: =COUNTIF('3'!$B$41:$C$46,$C$17) -> 0 | G17: =COUNTIF('4'!$B$41:$C$46,$C$17) -> 0 | H17: =COUNTIF('5'!$B$41:$C$46,$C$17) -> 0 | I17: =COUNTIF('6'!$B$41:$C$46,$C$17) -> 0 | J17: =COUNTIF('7'!$B$41:$C$46,$C$17) -> 0 | K17: =COUNTIF('8'!$B$41:$C$46,$C$17) -> 0 | L17: =COUNTIF('9'!$B$41:$C$46,$C$17) -> 0 | M17: =COUNTIF('10'!$B$41:$C$46,$C$17) -> 0 | N17: =COUNTIF('11'!$B$41:$C$46,$C$17) -> 0 | O17: =COUNTIF('12'!$B$41:$C$46,$C$17) -> 0 | P17: =COUNTIF('13'!$B$41:$C$46,$C$17) -> 0 | Q17: =COUNTIF('14'!$B$41:$C$46,$C$17) -> 0 | R17: =COUNTIF('15'!$B$41:$C$46,$C$17) -> 0 | S17: =COUNTIF('16'!$B$41:$C$46,$C$17) -> 0 | T17: =COUNTIF('17'!$B$41:$C$46,$C$17) -> 0 | U17: =COUNTIF('18'!$B$41:$C$46,$C$17) -> 0 | V17: =COUNTIF('19'!$B$41:$C$46,$C$17) -> 0 | W17: =COUNTIF('20'!$B$41:$C$46,$C$17) -> 0 | X17: =COUNTIF('21'!$B$41:$C$46,$C$17) -> 0 | Y17: =COUNTIF('22'!$B$41:$C$46,$C$17) -> 0 | Z17: =COUNTIF('23'!$B$41:$C$46,$C$17) -> 0 | AA17: =COUNTIF('24'!$B$41:$C$46,$C$17) -> 0 | AB17: =COUNTIF('25'!$B$41:$C$46,$C$17) -> 0 | AC17: =COUNTIF('26'!$B$41:$C$46,$C$17) -> 0 | AD17: =COUNTIF('27'!$B$41:$C$46,$C$17) -> 0 | AE17: =COUNTIF('28'!$B$41:$C$46,$C$17) -> 0 | AF17: =COUNTIF('29'!$B$41:$C$46,$C$17) -> 0 | AG17: =COUNTIF('30'!$B$41:$C$46,$C$17) -> 0 | AH17: =COUNTIF('31'!$B$41:$C$46,$C$17) -> 0 | AI17: =SUM(D17:AH17) -> 0 | AM17: 14 | AN17: ='14'!$G$2 -> 현대 | AO17: ='14'!$C$5 -> 3068000 | AP17: ='14'!$C$22 -> 767000 | AQ17: ='14'!$C$23 -> 2206000 | AR17: ='14'!$C$15 -> 836130 | AS17: ='14'!$C$17 -> 0.27253259 | AT17: ='14'!$C$36 -> 95000 | AU17: ='14'!$C$19 -> 741130 | AV17: =IFERROR(AO17/AY17,0) -> 1022666.7 | AW17: =VLOOKUP(AX17,IF({1,0},'14'!$AI$8:'14'!$AI$75,'14'!$AD$8:$AD$75),2,0) -> 꽃게사게 | AX17: =MAX('14'!$AI$8:$AI$35,'14'!$AI$39:$AI$62,'14'!$AI$66:$AI$75) -> 416000 | AY17: ='14'!$C$39 -> 3 | AZ17: ='14'!$B$41 -> 이웅 | BA17: ='14'!$B$42 -> 배기성 | BB17: ='14'!$B$43 -> 문효영 | BC17: ='14'!$B$44 -> 0 | BD17: ='14'!$B$45 -> 0 | BE17: ='14'!$B$46 -> 0 | BF17: ='14'!$C$41 -> 0 | BG17: ='14'!$C$42 -> 0 | BH17: ='14'!$C$43 -> 0 | BI17: ='14'!$C$44 -> 0 | BJ17: ='14'!$C$45 -> 0 | BK17: ='14'!$C$46 -> 0 | BL17: ='14'!$AH$4 -> 895878.68 | BM17: 13 | BN17: ='13'!C7 -> 2851000 | BP17: 29 | BQ17: ='29'!C7 -> 0
B18: 14 | D18: =COUNTIF('1'!$B$41:$C$46,$C$18) -> 0 | E18: =COUNTIF('2'!$B$41:$C$46,$C$18) -> 0 | F18: =COUNTIF('3'!$B$41:$C$46,$C$18) -> 0 | G18: =COUNTIF('4'!$B$41:$C$46,$C$18) -> 0 | H18: =COUNTIF('5'!$B$41:$C$46,$C$18) -> 0 | I18: =COUNTIF('6'!$B$41:$C$46,$C$18) -> 0 | J18: =COUNTIF('7'!$B$41:$C$46,$C$18) -> 0 | K18: =COUNTIF('8'!$B$41:$C$46,$C$18) -> 0 | L18: =COUNTIF('9'!$B$41:$C$46,$C$18) -> 0 | M18: =COUNTIF('10'!$B$41:$C$46,$C$18) -> 0 | N18: =COUNTIF('11'!$B$41:$C$46,$C$18) -> 0 | O18: =COUNTIF('12'!$B$41:$C$46,$C$18) -> 0 | P18: =COUNTIF('13'!$B$41:$C$46,$C$18) -> 0 | Q18: =COUNTIF('14'!$B$41:$C$46,$C$18) -> 0 | R18: =COUNTIF('15'!$B$41:$C$46,$C$18) -> 0 | S18: =COUNTIF('16'!$B$41:$C$46,$C$18) -> 0 | T18: =COUNTIF('17'!$B$41:$C$46,$C$18) -> 0 | U18: =COUNTIF('18'!$B$41:$C$46,$C$18) -> 0 | V18: =COUNTIF('19'!$B$41:$C$46,$C$18) -> 0 | W18: =COUNTIF('20'!$B$41:$C$46,$C$18) -> 0 | X18: =COUNTIF('21'!$B$41:$C$46,$C$18) -> 0 | Y18: =COUNTIF('22'!$B$41:$C$46,$C$18) -> 0 | Z18: =COUNTIF('23'!$B$41:$C$46,$C$18) -> 0 | AA18: =COUNTIF('24'!$B$41:$C$46,$C$18) -> 0 | AB18: =COUNTIF('25'!$B$41:$C$46,$C$18) -> 0 | AC18: =COUNTIF('26'!$B$41:$C$46,$C$18) -> 0 | AD18: =COUNTIF('27'!$B$41:$C$46,$C$18) -> 0 | AE18: =COUNTIF('28'!$B$41:$C$46,$C$18) -> 0 | AF18: =COUNTIF('29'!$B$41:$C$46,$C$18) -> 0 | AG18: =COUNTIF('30'!$B$41:$C$46,$C$18) -> 0 | AH18: =COUNTIF('31'!$B$41:$C$46,$C$18) -> 0 | AI18: =SUM(D18:AH18) -> 0 | AM18: 15 | AN18: ='15'!$G$2 -> 현대 | AO18: ='15'!$C$5 -> 3776000 | AP18: ='15'!$C$22 -> 1109000 | AQ18: ='15'!$C$23 -> 2562000 | AR18: ='15'!$C$15 -> 1043870 | AS18: ='15'!$C$17 -> 0.27644862 | AT18: ='15'!$C$36 -> 105000 | AU18: ='15'!$C$19 -> 938870 | AV18: =IFERROR(AO18/AY18,0) -> 1258666.7 | AW18: =VLOOKUP(AX18,IF({1,0},'15'!$AI$8:'15'!$AI$75,'15'!$AD$8:$AD$75),2,0) -> 꽃게사게 | AX18: =MAX('15'!$AI$8:$AI$35,'15'!$AI$39:$AI$62,'15'!$AI$66:$AI$75) -> 720000 | AY18: ='15'!$C$39 -> 3 | AZ18: ='15'!$B$41 -> 이웅 | BA18: ='15'!$B$42 -> 배기성 | BB18: ='15'!$B$43 -> 문효영 | BC18: ='15'!$B$44 -> 0 | BD18: ='15'!$B$45 -> 0 | BE18: ='15'!$B$46 -> 0 | BF18: ='15'!$C$41 -> 0 | BG18: ='15'!$C$42 -> 0 | BH18: ='15'!$C$43 -> 0 | BI18: ='15'!$C$44 -> 0 | BJ18: ='15'!$C$45 -> 0 | BK18: ='15'!$C$46 -> 0 | BL18: ='15'!$AH$4 -> 44180 | BM18: 14 | BN18: ='14'!C7 -> 3349000 | BP18: 30 | BQ18: ='30'!C7 -> 0
B19: 15 | D19: =COUNTIF('1'!$B$41:$C$46,$C$19) -> 0 | E19: =COUNTIF('2'!$B$41:$C$46,$C$19) -> 0 | F19: =COUNTIF('3'!$B$41:$C$46,$C$19) -> 0 | G19: =COUNTIF('4'!$B$41:$C$46,$C$19) -> 0 | H19: =COUNTIF('5'!$B$41:$C$46,$C$19) -> 0 | I19: =COUNTIF('6'!$B$41:$C$46,$C$19) -> 0 | J19: =COUNTIF('7'!$B$41:$C$46,$C$19) -> 0 | K19: =COUNTIF('8'!$B$41:$C$46,$C$19) -> 0 | L19: =COUNTIF('9'!$B$41:$C$46,$C$19) -> 0 | M19: =COUNTIF('10'!$B$41:$C$46,$C$19) -> 0 | N19: =COUNTIF('11'!$B$41:$C$46,$C$19) -> 0 | O19: =COUNTIF('12'!$B$41:$C$46,$C$19) -> 0 | P19: =COUNTIF('13'!$B$41:$C$46,$C$19) -> 0 | Q19: =COUNTIF('14'!$B$41:$C$46,$C$19) -> 0 | R19: =COUNTIF('15'!$B$41:$C$46,$C$19) -> 0 | S19: =COUNTIF('16'!$B$41:$C$46,$C$19) -> 0 | T19: =COUNTIF('17'!$B$41:$C$46,$C$19) -> 0 | U19: =COUNTIF('18'!$B$41:$C$46,$C$19) -> 0 | V19: =COUNTIF('19'!$B$41:$C$46,$C$19) -> 0 | W19: =COUNTIF('20'!$B$41:$C$46,$C$19) -> 0 | X19: =COUNTIF('21'!$B$41:$C$46,$C$19) -> 0 | Y19: =COUNTIF('22'!$B$41:$C$46,$C$19) -> 0 | Z19: =COUNTIF('23'!$B$41:$C$46,$C$19) -> 0 | AA19: =COUNTIF('24'!$B$41:$C$46,$C$19) -> 0 | AB19: =COUNTIF('25'!$B$41:$C$46,$C$19) -> 0 | AC19: =COUNTIF('26'!$B$41:$C$46,$C$19) -> 0 | AD19: =COUNTIF('27'!$B$41:$C$46,$C$19) -> 0 | AE19: =COUNTIF('28'!$B$41:$C$46,$C$19) -> 0 | AF19: =COUNTIF('29'!$B$41:$C$46,$C$19) -> 0 | AG19: =COUNTIF('30'!$B$41:$C$46,$C$19) -> 0 | AH19: =COUNTIF('31'!$B$41:$C$46,$C$19) -> 0 | AI19: =SUM(D19:AH19) -> 0 | AM19: 16 | AN19: ='16'!$G$2 -> 현대 | AO19: ='16'!$C$5 -> 4242000 | AP19: ='16'!$C$22 -> 672000 | AQ19: ='16'!$C$23 -> 3365000 | AR19: ='16'!$C$15 -> 1122705 | AS19: ='16'!$C$17 -> 0.26466407 | AT19: ='16'!$C$36 -> 205000 | AU19: ='16'!$C$19 -> 917705 | AV19: =IFERROR(AO19/AY19,0) -> 1414000 | AW19: =VLOOKUP(AX19,IF({1,0},'16'!$AI$8:'16'!$AI$75,'16'!$AD$8:$AD$75),2,0) -> 꽃게사게B | AX19: =MAX('16'!$AI$8:$AI$35,'16'!$AI$39:$AI$62,'16'!$AI$66:$AI$75) -> 645000 | AY19: ='16'!$C$39 -> 3 | AZ19: ='16'!$B$41 -> 이웅 | BA19: ='16'!$B$42 -> 배기성 | BB19: ='16'!$B$43 -> 문효영 | BC19: ='16'!$B$44 -> 0 | BD19: ='16'!$B$45 -> 0 | BE19: ='16'!$B$46 -> 0 | BF19: ='16'!$C$41 -> 0 | BG19: ='16'!$C$42 -> 0 | BH19: ='16'!$C$43 -> 0 | BI19: ='16'!$C$44 -> 0 | BJ19: ='16'!$C$45 -> 0 | BK19: ='16'!$C$46 -> 0 | BL19: ='16'!$AH$4 -> 3950 | BM19: 15 | BN19: ='15'!C7 -> 2227000 | BP19: 31 | BQ19: ='31'!C7 -> 0
B20: 근무인원 | D20: =SUM(D5:D19) -> 3 | E20: =SUM(E5:E19) -> 3 | F20: =SUM(F5:F19) -> 0 | G20: =SUM(G5:G19) -> 3 | H20: =SUM(H5:H19) -> 3 | I20: =SUM(I5:I19) -> 3 | J20: =SUM(J5:J19) -> 3 | K20: =SUM(K5:K19) -> 3 | ... AH20: =SUM(AH5:AH19) -> 0 | AM20: 17 | AN20: ='17'!$G$2 -> 현대 | AO20: ='17'!$C$5 -> 0 | AP20: ='17'!$C$22 -> 0 | AQ20: ='17'!$C$23 -> 0 | AR20: ='17'!$C$15 -> 0 | AS20: ='17'!$C$17 -> 0 | AT20: ='17'!$C$36 -> 0 | AU20: ='17'!$C$19 -> 0 | AV20: =IFERROR(AO20/AY20,0) -> 0 | AW20: =VLOOKUP(AX20,IF({1,0},'17'!$AI$8:'17'!$AI$75,'17'!$AD$8:$AD$75),2,0) -> 냉)포크오징어M2 | AX20: =MAX('17'!$AI$8:$AI$35,'17'!$AI$39:$AI$62,'17'!$AI$66:$AI$75) -> 0 | AY20: ='17'!$C$39 -> 0 | AZ20: ='17'!$B$41 -> 0 | BA20: ='17'!$B$42 -> 0 | BB20: ='17'!$B$43 -> 0 | BC20: ='17'!$B$44 -> 0 | BD20: ='17'!$B$45 -> 0 | BE20: ='17'!$B$46 -> 0 | BF20: ='17'!$C$41 -> 0 | BG20: ='17'!$C$42 -> 0 | BH20: ='17'!$C$43 -> 0 | BI20: ='17'!$C$44 -> 0 | BJ20: ='17'!$C$45 -> 0 | BK20: ='17'!$C$46 -> 0 | BL20: ='17'!$AH$4 -> 0 | BM20: 16 | BN20: ='16'!C7 -> 3309500 | BP20: 합계 | BQ20: =SUM(BN5:BN20)+SUM(BQ5:BQ19) -> 54041000
AM21: 18 | AN21: ='18'!$G$2 -> 현대 | AO21: ='18'!$C$5 -> 3145000 | AP21: ='18'!$C$22 -> 893000 | AQ21: ='18'!$C$23 -> 2147000 | AR21: ='18'!$C$15 -> 822350 | AS21: ='18'!$C$17 -> 0.26147854 | AT21: ='18'!$C$36 -> 105000 | AU21: ='18'!$C$19 -> 717350 | AV21: =IFERROR(AO21/AY21,0) -> 1048333.3 | AW21: =VLOOKUP(AX21,IF({1,0},'18'!$AI$8:'18'!$AI$75,'18'!$AD$8:$AD$75),2,0) -> 꽃게사게A | AX21: =MAX('18'!$AI$8:$AI$35,'18'!$AI$39:$AI$62,'18'!$AI$66:$AI$75) -> 630000 | AY21: ='18'!$C$39 -> 3 | AZ21: ='18'!$B$41 -> 이웅 | BA21: ='18'!$B$42 -> 배기성 | BB21: ='18'!$B$43 -> 문효영 | BC21: ='18'!$B$44 -> 0 | BD21: ='18'!$B$45 -> 0 | BE21: ='18'!$B$46 -> 0 | BF21: ='18'!$C$41 -> 0 | BG21: ='18'!$C$42 -> 0 | BH21: ='18'!$C$43 -> 0 | BI21: ='18'!$C$44 -> 0 | BJ21: ='18'!$C$45 -> 0 | BK21: ='18'!$C$46 -> 0 | BL21: ='18'!$AH$4 -> -9870
B22: 지각 및 조퇴 | AM22: 19 | AN22: ='19'!$G$2 -> 현대 | AO22: ='19'!$C$5 -> 3625000 | AP22: ='19'!$C$22 -> 1166000 | AQ22: ='19'!$C$23 -> 2334000 | AR22: ='19'!$C$15 -> 990610 | AS22: ='19'!$C$17 -> 0.27327172 | AT22: ='19'!$C$36 -> 125000 | AU22: ='19'!$C$19 -> 865610 | AV22: =IFERROR(AO22/AY22,0) -> 1208333.3 | AW22: =VLOOKUP(AX22,IF({1,0},'19'!$AI$8:'19'!$AI$75,'19'!$AD$8:$AD$75),2,0) -> 꽃게사게B | AX22: =MAX('19'!$AI$8:$AI$35,'19'!$AI$39:$AI$62,'19'!$AI$66:$AI$75) -> 546000 | AY22: ='19'!$C$39 -> 3 | AZ22: ='19'!$B$41 -> 이웅 | BA22: ='19'!$B$42 -> 배기성 | BB22: ='19'!$B$43 -> 문효영 | BC22: ='19'!$B$44 -> 0 | BD22: ='19'!$B$45 -> 0 | BE22: ='19'!$B$46 -> 0 | BF22: ='19'!$C$41 -> 0 | BG22: ='19'!$C$42 -> 0 | BH22: ='19'!$C$43 -> 0 | BI22: ='19'!$C$44 -> 0 | BJ22: ='19'!$C$45 -> 0 | BK22: ='19'!$C$46 -> 0 | BL22: ='19'!$AH$4 -> 93199
B23: 날짜 | D23: 이름 | H23: 내용 | L23: 사유 | AM23: 20 | AN23: ='20'!$G$2 -> 현대 | AO23: ='20'!$C$5 -> 2017000 | AP23: ='20'!$C$22 -> 705000 | AQ23: ='20'!$C$23 -> 1221000 | AR23: ='20'!$C$15 -> 528790 | AS23: ='20'!$C$17 -> 0.26216658 | AT23: ='20'!$C$36 -> 91000 | AU23: ='20'!$C$19 -> 437790 | AV23: =IFERROR(AO23/AY23,0) -> 672333.33 | AW23: =VLOOKUP(AX23,IF({1,0},'20'!$AI$8:'20'!$AI$75,'20'!$AD$8:$AD$75),2,0) -> 제주갈치36-40미 | AX23: =MAX('20'!$AI$8:$AI$35,'20'!$AI$39:$AI$62,'20'!$AI$66:$AI$75) -> 231000 | AY23: ='20'!$C$39 -> 3 | AZ23: ='20'!$B$41 -> 이웅 | BA23: ='20'!$B$42 -> 배기성 | BB23: ='20'!$B$43 -> 문효영 | BC23: ='20'!$B$44 -> 0 | BD23: ='20'!$B$45 -> 0 | BE23: ='20'!$B$46 -> 0 | BF23: ='20'!$C$41 -> 0 | BG23: ='20'!$C$42 -> 0 | BH23: ='20'!$C$43 -> 0 | BI23: ='20'!$C$44 -> 0 | BJ23: ='20'!$C$45 -> 0 | BK23: ='20'!$C$46 -> 0 | BL23: ='20'!$AH$4 -> 178330
B24: 날짜 | D24: 이름 | H24: 내용 | L24: 사유 | AM24: 21 | AN24: ='21'!$G$2 -> 현대 | AO24: ='21'!$C$5 -> 2919000 | AP24: ='21'!$C$22 -> 866000 | AQ24: ='21'!$C$23 -> 1873000 | AR24: ='21'!$C$15 -> 790600 | AS24: ='21'!$C$17 -> 0.27084618 | AT24: ='21'!$C$36 -> 180000 | AU24: ='21'!$C$19 -> 610600 | AV24: =IFERROR(AO24/AY24,0) -> 973000 | AW24: =VLOOKUP(AX24,IF({1,0},'21'!$AI$8:'21'!$AI$75,'21'!$AD$8:$AD$75),2,0) -> 제주갈치31-35미 | AX24: =MAX('21'!$AI$8:$AI$35,'21'!$AI$39:$AI$62,'21'!$AI$66:$AI$75) -> 341000 | AY24: ='21'!$C$39 -> 3 | AZ24: ='21'!$B$41 -> 이웅 | BA24: ='21'!$B$42 -> 배기성 | BB24: ='21'!$B$43 -> 문효영 | BC24: ='21'!$B$44 -> 0 | BD24: ='21'!$B$45 -> 0 | BE24: ='21'!$B$46 -> 0 | BF24: ='21'!$C$41 -> 0 | BG24: ='21'!$C$42 -> 0 | BH24: ='21'!$C$43 -> 0 | BI24: ='21'!$C$44 -> 0 | BJ24: ='21'!$C$45 -> 0 | BK24: ='21'!$C$46 -> 0 | BL24: ='21'!$AH$4 -> 43593.333
B25: 날짜 | D25: 이름 | H25: 내용 | L25: 사유 | AM25: 22 | AN25: ='22'!$G$2 -> 현대 | AO25: ='22'!$C$5 -> 2848000 | AP25: ='22'!$C$22 -> 763000 | AQ25: ='22'!$C$23 -> 2000000 | AR25: ='22'!$C$15 -> 785640 | AS25: ='22'!$C$17 -> 0.27585674 | AT25: ='22'!$C$36 -> 85000 | AU25: ='22'!$C$19 -> 700640 | AV25: =IFERROR(AO25/AY25,0) -> 949333.33 | AW25: =VLOOKUP(AX25,IF({1,0},'22'!$AI$8:'22'!$AI$75,'22'!$AD$8:$AD$75),2,0) -> 제주갈치31-35미 | AX25: =MAX('22'!$AI$8:$AI$35,'22'!$AI$39:$AI$62,'22'!$AI$66:$AI$75) -> 341647.06 | AY25: ='22'!$C$39 -> 3 | AZ25: ='22'!$B$41 -> 이웅 | BA25: ='22'!$B$42 -> 배기성 | BB25: ='22'!$B$43 -> 문효영 | BC25: ='22'!$B$44 -> 0 | BD25: ='22'!$B$45 -> 0 | BE25: ='22'!$B$46 -> 0 | BF25: ='22'!$C$41 -> 0 | BG25: ='22'!$C$42 -> 0 | BH25: ='22'!$C$43 -> 0 | BI25: ='22'!$C$44 -> 0 | BJ25: ='22'!$C$45 -> 0 | BK25: ='22'!$C$46 -> 0 | BL25: ='22'!$AH$4 -> 87272.941
B26: 날짜 | D26: 이름 | H26: 내용 | L26: 사유 | AM26: 23 | AN26: ='23'!$G$2 -> 현대 | AO26: ='23'!$C$5 -> 3874000 | AP26: ='23'!$C$22 -> 903000 | AQ26: ='23'!$C$23 -> 2866000 | AR26: ='23'!$C$15 -> 1066540 | AS26: ='23'!$C$17 -> 0.27530718 | AT26: ='23'!$C$36 -> 105000 | AU26: ='23'!$C$19 -> 961540 | AV26: =IFERROR(AO26/AY26,0) -> 1291333.3 | AW26: =VLOOKUP(AX26,IF({1,0},'23'!$AI$8:'23'!$AI$75,'23'!$AD$8:$AD$75),2,0) -> 꽃게사게 | AX26: =MAX('23'!$AI$8:$AI$35,'23'!$AI$39:$AI$62,'23'!$AI$66:$AI$75) -> 504000 | AY26: ='23'!$C$39 -> 3 | AZ26: ='23'!$B$41 -> 이웅 | BA26: ='23'!$B$42 -> 배기성 | BB26: ='23'!$B$43 -> 문효영 | BC26: ='23'!$B$44 -> 0 | BD26: ='23'!$B$45 -> 0 | BE26: ='23'!$B$46 -> 0 | BF26: ='23'!$C$41 -> 0 | BG26: ='23'!$C$42 -> 0 | BH26: ='23'!$C$43 -> 0 | BI26: ='23'!$C$44 -> 0 | BJ26: ='23'!$C$45 -> 0 | BK26: ='23'!$C$46 -> 0 | BL26: ='23'!$AH$4 -> -27760
B27: 날짜 | D27: 이름 | H27: 내용 | L27: 사유 | AM27: 24 | AN27: ='24'!$G$2 -> 현대 | AO27: ='24'!$C$5 -> 0 | AP27: ='24'!$C$22 -> 0 | AQ27: ='24'!$C$23 -> 0 | AR27: ='24'!$C$15 -> 0 | AS27: ='24'!$C$17 -> 0 | AT27: ='24'!$C$36 -> 0 | AU27: ='24'!$C$19 -> 0 | AV27: =IFERROR(AO27/AY27,0) -> 0 | AW27: =VLOOKUP(AX27,IF({1,0},'24'!$AI$8:'24'!$AI$75,'24'!$AD$8:$AD$75),2,0) -> 냉)포크오징어M2 | AX27: =MAX('24'!$AI$8:$AI$35,'24'!$AI$39:$AI$62,'24'!$AI$66:$AI$75) -> 0 | AY27: ='24'!$C$39 -> 0 | AZ27: ='24'!$B$41 -> 0 | BA27: ='24'!$B$42 -> 0 | BB27: ='24'!$B$43 -> 0 | BC27: ='24'!$B$44 -> 0 | BD27: ='24'!$B$45 -> 0 | BE27: ='24'!$B$46 -> 0 | BF27: ='24'!$C$41 -> 0 | BG27: ='24'!$C$42 -> 0 | BH27: ='24'!$C$43 -> 0 | BI27: ='24'!$C$44 -> 0 | BJ27: ='24'!$C$45 -> 0 | BK27: ='24'!$C$46 -> 0 | BL27: ='24'!$AH$4 -> 0
B28: 날짜 | D28: 이름 | H28: 내용 | L28: 사유 | AM28: 25 | AN28: ='25'!$G$2 -> 현대 | AO28: ='25'!$C$5 -> 3008000 | AP28: ='25'!$C$22 -> 890000 | AQ28: ='25'!$C$23 -> 2005000 | AR28: ='25'!$C$15 -> 839490 | AS28: ='25'!$C$17 -> 0.27908577 | AT28: ='25'!$C$36 -> 113000 | AU28: ='25'!$C$19 -> 726490 | AV28: =IFERROR(AO28/AY28,0) -> 1002666.7 | AW28: =VLOOKUP(AX28,IF({1,0},'25'!$AI$8:'25'!$AI$75,'25'!$AD$8:$AD$75),2,0) -> 꽃게사게 | AX28: =MAX('25'!$AI$8:$AI$35,'25'!$AI$39:$AI$62,'25'!$AI$66:$AI$75) -> 441000 | AY28: ='25'!$C$39 -> 3 | AZ28: ='25'!$B$41 -> 이웅 | BA28: ='25'!$B$42 -> 배기성 | BB28: ='25'!$B$43 -> 문효영 | BC28: ='25'!$B$44 -> 0 | BD28: ='25'!$B$45 -> 0 | BE28: ='25'!$B$46 -> 0 | BF28: ='25'!$C$41 -> 0 | BG28: ='25'!$C$42 -> 0 | BH28: ='25'!$C$43 -> 0 | BI28: ='25'!$C$44 -> 0 | BJ28: ='25'!$C$45 -> 0 | BK28: ='25'!$C$46 -> 0 | BL28: ='25'!$AH$4 -> -61020
B29: 날짜 | D29: 이름 | H29: 내용 | L29: 사유 | AM29: 26 | AN29: ='26'!$G$2 -> 현대 | AO29: ='26'!$C$5 -> 3491000 | AP29: ='26'!$C$22 -> 1270000 | AQ29: ='26'!$C$23 -> 2151000 | AR29: ='26'!$C$15 -> 989830 | AS29: ='26'!$C$17 -> 0.28353767 | AT29: ='26'!$C$36 -> 70000 | AU29: ='26'!$C$19 -> 919830 | AV29: =IFERROR(AO29/AY29,0) -> 1745500 | AW29: =VLOOKUP(AX29,IF({1,0},'26'!$AI$8:'26'!$AI$75,'26'!$AD$8:$AD$75),2,0) -> 꽃게사게 | AX29: =MAX('26'!$AI$8:$AI$35,'26'!$AI$39:$AI$62,'26'!$AI$66:$AI$75) -> 707000 | AY29: ='26'!$C$39 -> 2 | AZ29: ='26'!$B$41 -> 이웅 | BA29: ='26'!$B$42 -> 배기성 | BB29: ='26'!$B$43 -> 0 | BC29: ='26'!$B$44 -> 0 | BD29: ='26'!$B$45 -> 0 | BE29: ='26'!$B$46 -> 0 | BF29: ='26'!$C$41 -> 0 | BG29: ='26'!$C$42 -> 0 | BH29: ='26'!$C$43 -> 0 | BI29: ='26'!$C$44 -> 0 | BJ29: ='26'!$C$45 -> 0 | BK29: ='26'!$C$46 -> 0 | BL29: ='26'!$AH$4 -> 16189
B30: 날짜 | D30: 이름 | H30: 내용 | L30: 사유 | AM30: 27 | AN30: ='27'!$G$2 -> 현대 | AO30: ='27'!$C$5 -> 0 | AP30: ='27'!$C$22 -> 0 | AQ30: ='27'!$C$23 -> 0 | AR30: ='27'!$C$15 -> -4805690 | AS30: ='27'!$C$17 -> 0 | AT30: ='27'!$C$36 -> 0 | AU30: ='27'!$C$19 -> -4805690 | AV30: =IFERROR(AO30/AY30,0) -> 0 | AW30: =VLOOKUP(AX30,IF({1,0},'27'!$AI$8:'27'!$AI$75,'27'!$AD$8:$AD$75),2,0) | AX30: =MAX('27'!$AI$8:$AI$35,'27'!$AI$39:$AI$62,'27'!$AI$66:$AI$75) -> 0 | AY30: ='27'!$C$39 -> 0 | AZ30: ='27'!$B$41 -> 0 | BA30: ='27'!$B$42 -> 0 | BB30: ='27'!$B$43 -> 0 | BC30: ='27'!$B$44 -> 0 | BD30: ='27'!$B$45 -> 0 | BE30: ='27'!$B$46 -> 0 | BF30: ='27'!$C$41 -> 0 | BG30: ='27'!$C$42 -> 0 | BH30: ='27'!$C$43 -> 0 | BI30: ='27'!$C$44 -> 0 | BJ30: ='27'!$C$45 -> 0 | BK30: ='27'!$C$46 -> 0 | BL30: ='27'!$AH$4 -> 0
AM31: 28 | AN31: ='28'!$G$2 -> 현대 | AO31: ='28'!$C$5 -> 0 | AP31: ='28'!$C$22 -> 0 | AQ31: ='28'!$C$23 -> 0 | AR31: ='28'!$C$15 -> 0 | AS31: ='28'!$C$17 -> 0 | AT31: ='28'!$C$36 -> 0 | AU31: ='28'!$C$19 -> 0 | AV31: =IFERROR(AO31/AY31,0) -> 0 | AW31: =VLOOKUP(AX31,IF({1,0},'28'!$AI$8:'28'!$AI$75,'28'!$AD$8:$AD$75),2,0) | AX31: =MAX('28'!$AI$8:$AI$35,'28'!$AI$39:$AI$62,'28'!$AI$66:$AI$75) -> 0 | AY31: ='28'!$C$39 -> 0 | AZ31: ='28'!$B$41 -> 0 | BA31: ='28'!$B$42 -> 0 | BB31: ='28'!$B$43 -> 0 | BC31: ='28'!$B$44 -> 0 | BD31: ='28'!$B$45 -> 0 | BE31: ='28'!$B$46 -> 0 | BF31: ='28'!$C$41 -> 0 | BG31: ='28'!$C$42 -> 0 | BH31: ='28'!$C$43 -> 0 | BI31: ='28'!$C$44 -> 0 | BJ31: ='28'!$C$45 -> 0 | BK31: ='28'!$C$46 -> 0 | BL31: ='28'!$AH$4 -> 0
B32: 재고금액변동 | AM32: 29 | AN32: ='29'!$G$2 -> 현대 | AO32: ='29'!$C$5 -> 0 | AP32: ='29'!$C$22 -> 0 | AQ32: ='29'!$C$23 -> 0 | AR32: ='29'!$C$15 -> 0 | AS32: ='29'!$C$17 -> 0 | AT32: ='29'!$C$36 -> 0 | AU32: ='29'!$C$19 -> 0 | AV32: =IFERROR(AO32/AY32,0) -> 0 | AW32: =VLOOKUP(AX32,IF({1,0},'29'!$AI$8:'29'!$AI$75,'29'!$AD$8:$AD$75),2,0) | AX32: =MAX('29'!$AI$8:$AI$35,'29'!$AI$39:$AI$62,'29'!$AI$66:$AI$75) -> 0 | AY32: ='29'!$C$39 -> 0 | AZ32: ='29'!$B$41 -> 0 | BA32: ='29'!$B$42 -> 0 | BB32: ='29'!$B$43 -> 0 | BC32: ='29'!$B$44 -> 0 | BD32: ='29'!$B$45 -> 0 | BE32: ='29'!$B$46 -> 0 | BF32: ='29'!$C$41 -> 0 | BG32: ='29'!$C$42 -> 0 | BH32: ='29'!$C$43 -> 0 | BI32: ='29'!$C$44 -> 0 | BJ32: ='29'!$C$45 -> 0 | BK32: ='29'!$C$46 -> 0 | BL32: ='29'!$AH$4 -> 0
B33: ='31'!C11-'1'!C9 -> -5228260 | AM33: 30 | AN33: ='30'!$G$2 -> 현대 | AO33: ='30'!$C$5 -> 0 | AP33: ='30'!$C$22 -> 0 | AQ33: ='30'!$C$23 -> 0 | AR33: ='30'!$C$15 -> 0 | AS33: ='30'!$C$17 -> 0 | AT33: ='30'!$C$36 -> 0 | AU33: ='30'!$C$19 -> 0 | AV33: =IFERROR(AO33/AY33,0) -> 0 | AW33: =VLOOKUP(AX33,IF({1,0},'30'!$AI$8:'30'!$AI$75,'30'!$AD$8:$AD$75),2,0) | AX33: =MAX('30'!$AI$8:$AI$35,'30'!$AI$39:$AI$62,'30'!$AI$66:$AI$75) -> 0 | AY33: ='30'!$C$39 -> 0 | AZ33: ='30'!$B$41 -> 0 | BA33: ='30'!$B$42 -> 0 | BB33: ='30'!$B$43 -> 0 | BC33: ='30'!$B$44 -> 0 | BD33: ='30'!$B$45 -> 0 | BE33: ='30'!$B$46 -> 0 | BF33: ='30'!$C$41 -> 0 | BG33: ='30'!$C$42 -> 0 | BH33: ='30'!$C$43 -> 0 | BI33: ='30'!$C$44 -> 0 | BJ33: ='30'!$C$45 -> 0 | BK33: ='30'!$C$46 -> 0 | BL33: ='30'!$AH$4 -> 0
AM34: 31 | AN34: ='31'!$G$2 -> 현대 | AO34: ='31'!$C$5 -> 0 | AP34: ='31'!$C$22 -> 0 | AQ34: ='31'!$C$23 -> 0 | AR34: ='31'!$C$15 -> 0 | AS34: ='31'!$C$17 -> 0 | AT34: ='31'!$C$36 -> 0 | AU34: ='31'!$C$19 -> 0 | AV34: =IFERROR(AO34/AY34,0) -> 0 | AW34: =VLOOKUP(AX34,IF({1,0},'31'!$AI$8:'31'!$AI$75,'31'!$AD$8:$AD$75),2,0) | AX34: =MAX('31'!$AI$8:$AI$35,'31'!$AI$39:$AI$62,'31'!$AI$66:$AI$75) -> 0 | AY34: ='31'!$C$39 -> 0 | AZ34: ='31'!$B$41 -> 0 | BA34: ='31'!$B$42 -> 0 | BB34: ='31'!$B$43 -> 0 | BC34: ='31'!$B$44 -> 0 | BD34: ='31'!$B$45 -> 0 | BE34: ='31'!$B$46 -> 0 | BF34: ='31'!$C$41 -> 0 | BG34: ='31'!$C$42 -> 0 | BH34: ='31'!$C$43 -> 0 | BI34: ='31'!$C$44 -> 0 | BJ34: ='31'!$C$45 -> 0 | BK34: ='31'!$C$46 -> 0 | BL34: ='31'!$AH$4 -> 0
AM35: 합계 | AO35: =SUM(AO4:AO34) -> 74977000 | AP35: =SUM(AP4:AP34) -> 21980000 | AQ35: =SUM(AQ4:AQ34) -> 50479000 | AS35: =IFERROR((AU35+AT35)/AO35,0) -> 0.20950078 | AT35: =SUM(AT4:AT34) -> 2518000 | AU35: =SUM(AU4:AU34) -> 13189740 | BL35: =SUM(BL4:BL34) -> 1657451

Sheet 이월
W1: <-- 보고 절취선
B2: 2026년 월 일 | F2: 지점 | G2: 현대 | J2: 전달 사항 | AD2: 관리자모드 - 매출 분석
B4: 매입금 임시 작성칸 | E4: 냉동 | N4: 생물 | AD4: 매출 | AE4: =AI36+AI63+AI76 -> -5288060 | AG4: 차이 | AH4: =C5-AE4-(SUM(R34:S38)) -> 5288060 | AL4: 이익률 계산기 | AQ4: * 마리수 세기 힘들때는 바구니 수로 대체
B5: 매출 | C5: =C22+C23+C24+C36 -> 0 | E5: NO | F5: 품목 | G5: 규격 | H5: 단가 | I5: 재고량 | J5: 재고금액 | K5: 박스당 판매단가 | L5: 30%단가 | N5: NO | O5: 품목 | P5: 규격 | Q5: 단가 | R5: 재고량 | S5: 재고금액 | T5: 박스당 판매단가 | U5: 30%단가 | AD5: 이익률 | AE5: =IFERROR(((AE4-(AG36+AG63+AG76))/AE4),0) -> 0.011308495 | AG5: 차이 | AH5: =IFERROR(C17-AE5-((SUM(R34:S38))/C5),0) -> 0 | AL5: 품목 | AM5: 규격 | AN5: 매입가 | AO5: 마리수 | AP5: 마리당 단가 | AQ5: 판매마리수 | AR5: 판매가 | AS5: 마진율 | AT5: 박스당 판매단가
E6: 1 | F6: 냉)포크오징어 | G6: M2 | H6: 184000 | I6: 2 | J6: =H6*I6 -> 368000 | L6: =IF(H6="","",H6/0.7) -> 262857.14 | N6: 1 | O6: 전복 | P6: 10미 | Q6: 195000 | R6: 2.54 | S6: =Q6*R6 -> 495300 | U6: =IF(Q6="","",Q6/0.7) -> 278571.43 | AD6: 냉동 | AP6: =IFERROR(AN6/AO6,0) -> 0 | AS6: =IFERROR(((AR6-(AP6*AQ6))/AR6),0) -> 0 | AT6: =IFERROR((AR6/AQ6)*AO6,0) -> 0
B7: 매입 | C7: =IF(C4="",L86,C4) -> 0 | E7: 2 | F7: 냉)꽃게 | G7: 숫200-300 | H7: 30000 | I7: 2.17 | J7: =H7*I7 -> 65100 | L7: =IF(H7="","",H7/0.7) -> 42857.143 | N7: 2 | O7: 전복 | P7: 20미 | Q7: 160000 | R7: 2.44 | S7: =Q7*R7 -> 390400 | U7: =IF(Q7="","",Q7/0.7) -> 228571.43 | X7: NO | Y7: 품목규격 | Z7: 재고금액 | AC7: NO | AD7: 품목규격 | AE7: 전재고 | AF7: 매입 | AG7: 판매원가 | AH7: 이익률 | AI7: 판매금액 | AJ7: 판매량 | AP7: =IFERROR(AN7/AO7,0) -> 0 | AS7: =IFERROR(((AR7-(AP7*AQ7))/AR7),0) -> 0 | AT7: =IFERROR((AR7/AQ7)*AO7,0) -> 0
E8: 3 | F8: 냉)낙지 | G8: 150-200 | H8: 48000 | I8: 2 | J8: =H8*I8 -> 96000 | L8: =IF(H8="","",H8/0.7) -> 68571.429 | N8: 3 | O8: 멍게 | Q8: 2500 | R8: 27.5 | S8: =Q8*R8 -> 68750 | U8: =IF(Q8="","",Q8/0.7) -> 3571.4286 | X8: 1 | Y8: =F6&G6 -> 냉)포크오징어M2 | Z8: =J6 -> 368000 | AC8: 1 | AD8: =F6&G6 -> 냉)포크오징어M2 | AE8: =IFERROR(VLOOKUP(AD8,이월!$W$8:$X$69,2,0),0) -> 0 | AF8: =IFERROR(VLOOKUP(AD8,$K$51:$L$85,2,0),0) -> 0 | AG8: =AE8+AF8-J6 -> -368000 | AH8: =IFERROR((K6-H6)/K6,0) -> 0 | AI8: =IFERROR(AG8/(1-AH8),0) -> -368000 | AJ8: =IFERROR(AG8/H6,0) -> -2 | AP8: =IFERROR(AN8/AO8,0) -> 0 | AS8: =IFERROR(((AR8-(AP8*AQ8))/AR8),0) -> 0 | AT8: =IFERROR((AR8/AQ8)*AO8,0) -> 0
B9: 전일재고 | E9: 4 | F9: 냉)동태포 | G9: 15팩 | H9: 28500 | I9: 1 | J9: =H9*I9 -> 28500 | L9: =IF(H9="","",H9/0.7) -> 40714.286 | N9: 4 | O9: 냉)초코오징어 | P9: 30미 | Q9: 68000 | R9: 1.46 | S9: =Q9*R9 -> 99280 | U9: =IF(Q9="","",Q9/0.7) -> 97142.857 | X9: 2 | Y9: =F7&G7 -> 냉)꽃게숫200-300 | Z9: =J7 -> 65100 | AC9: 2 | AD9: =F7&G7 -> 냉)꽃게숫200-300 | AE9: =IFERROR(VLOOKUP(AD9,이월!$W$8:$X$69,2,0),0) -> 0 | AF9: =IFERROR(VLOOKUP(AD9,$K$51:$L$85,2,0),0) -> 0 | AG9: =AE9+AF9-J7 -> -65100 | AH9: =IFERROR((K7-H7)/K7,0) -> 0 | AI9: =IFERROR(AG9/(1-AH9),0) -> -65100 | AJ9: =IFERROR(AG9/H7,0) -> -2.17 | AP9: =IFERROR(AN9/AO9,0) -> 0 | AS9: =IFERROR(((AR9-(AP9*AQ9))/AR9),0) -> 0 | AT9: =IFERROR((AR9/AQ9)*AO9,0) -> 0
E10: 5 | F10: 냉)선동제주갈치 | G10: 31-33 | H10: 135000 | I10: 2.54 | J10: =H10*I10 -> 342900 | L10: =IF(H10="","",H10/0.7) -> 192857.14 | N10: 5 | O10: 제주갈치 | P10: 10미 | Q10: 140000 | R10: 0.7 | S10: =Q10*R10 -> 98000 | U10: =IF(Q10="","",Q10/0.7) -> 200000 | X10: 3 | Y10: =F8&G8 -> 냉)낙지150-200 | Z10: =J8 -> 96000 | AC10: 3 | AD10: =F8&G8 -> 냉)낙지150-200 | AE10: =IFERROR(VLOOKUP(AD10,이월!$W$8:$X$69,2,0),0) -> 0 | AF10: =IFERROR(VLOOKUP(AD10,$K$51:$L$85,2,0),0) -> 0 | AG10: =AE10+AF10-J8 -> -96000 | AH10: =IFERROR((K8-H8)/K8,0) -> 0 | AI10: =IFERROR(AG10/(1-AH10),0) -> -96000 | AJ10: =IFERROR(AG10/H8,0) -> -2 | AP10: =IFERROR(AN10/AO10,0) -> 0 | AS10: =IFERROR(((AR10-(AP10*AQ10))/AR10),0) -> 0 | AT10: =IFERROR((AR10/AQ10)*AO10,0) -> 0
B11: 당일재고 | C11: =J34+S30 -> 5228260 | E11: 6 | F11: 냉)자반고등어 | G11: 10손대 | H11: 79000 | I11: 2 | J11: =H11*I11 -> 158000 | L11: =IF(H11="","",H11/0.7) -> 112857.14 | N11: 6 | O11: 도미 | Q11: 26000 | R11: 0.4 | S11: =Q11*R11 -> 10400 | U11: =IF(Q11="","",Q11/0.7) -> 37142.857 | X11: 4 | Y11: =F9&G9 -> 냉)동태포15팩 | Z11: =J9 -> 28500 | AC11: 4 | AD11: =F9&G9 -> 냉)동태포15팩 | AE11: =IFERROR(VLOOKUP(AD11,이월!$W$8:$X$69,2,0),0) -> 0 | AF11: =IFERROR(VLOOKUP(AD11,$K$51:$L$85,2,0),0) -> 0 | AG11: =AE11+AF11-J9 -> -28500 | AH11: =IFERROR((K9-H9)/K9,0) -> 0 | AI11: =IFERROR(AG11/(1-AH11),0) -> -28500 | AJ11: =IFERROR(AG11/H9,0) -> -1 | AP11: =IFERROR(AN11/AO11,0) -> 0 | AS11: =IFERROR(((AR11-(AP11*AQ11))/AR11),0) -> 0 | AT11: =IFERROR((AR11/AQ11)*AO11,0) -> 0
E12: 7 | F12: 냉)참조기 | G12: 40-42 | H12: 29000 | I12: 3.39 | J12: =H12*I12 -> 98310 | L12: =IF(H12="","",H12/0.7) -> 41428.571 | N12: 7 | O12: 꽃게 | P12: 사게A | Q12: 10000 | R12: 29.4 | S12: =Q12*R12 -> 294000 | U12: =IF(Q12="","",Q12/0.7) -> 14285.714 | X12: 5 | Y12: =F10&G10 -> 냉)선동제주갈치31-33 | Z12: =J10 -> 342900 | AC12: 5 | AD12: =F10&G10 -> 냉)선동제주갈치31-33 | AE12: =IFERROR(VLOOKUP(AD12,이월!$W$8:$X$69,2,0),0) -> 0 | AF12: =IFERROR(VLOOKUP(AD12,$K$51:$L$85,2,0),0) -> 0 | AG12: =AE12+AF12-J10 -> -342900 | AH12: =IFERROR((K10-H10)/K10,0) -> 0 | AI12: =IFERROR(AG12/(1-AH12),0) -> -342900 | AJ12: =IFERROR(AG12/H10,0) -> -2.54 | AP12: =IFERROR(AN12/AO12,0) -> 0 | AS12: =IFERROR(((AR12-(AP12*AQ12))/AR12),0) -> 0 | AT12: =IFERROR((AR12/AQ12)*AO12,0) -> 0
B13: 매출원가 | C13: =C7+C9-C11 -> -5228260 | E13: 8 | F13: 냉)쭈꾸미 | G13: 100-150 | H13: 70000 | I13: 3 | J13: =H13*I13 -> 210000 | L13: =IF(H13="","",H13/0.7) -> 100000 | N13: 8 | O13: 바지락 | Q13: 38000 | R13: 1 | S13: =Q13*R13 -> 38000 | U13: =IF(Q13="","",Q13/0.7) -> 54285.714 | X13: 6 | Y13: =F11&G11 -> 냉)자반고등어10손대 | Z13: =J11 -> 158000 | AC13: 6 | AD13: =F11&G11 -> 냉)자반고등어10손대 | AE13: =IFERROR(VLOOKUP(AD13,이월!$W$8:$X$69,2,0),0) -> 0 | AF13: =IFERROR(VLOOKUP(AD13,$K$51:$L$85,2,0),0) -> 0 | AG13: =AE13+AF13-J11 -> -158000 | AH13: =IFERROR((K11-H11)/K11,0) -> 0 | AI13: =IFERROR(AG13/(1-AH13),0) -> -158000 | AJ13: =IFERROR(AG13/H11,0) -> -2 | AP13: =IFERROR(AN13/AO13,0) -> 0 | AS13: =IFERROR(((AR13-(AP13*AQ13))/AR13),0) -> 0 | AT13: =IFERROR((AR13/AQ13)*AO13,0) -> 0
E14: 9 | F14: 냉)부세 | G14: 150-200A | H14: 35000 | I14: 3 | J14: =H14*I14 -> 105000 | L14: =IF(H14="","",H14/0.7) -> 50000 | N14: 9 | O14: 낙지 | P14: 10미A | Q14: 27000 | R14: 2 | S14: =Q14*R14 -> 54000 | U14: =IF(Q14="","",Q14/0.7) -> 38571.429 | X14: 7 | Y14: =F12&G12 -> 냉)참조기40-42 | Z14: =J12 -> 98310 | AC14: 7 | AD14: =F12&G12 -> 냉)참조기40-42 | AE14: =IFERROR(VLOOKUP(AD14,이월!$W$8:$X$69,2,0),0) -> 0 | AF14: =IFERROR(VLOOKUP(AD14,$K$51:$L$85,2,0),0) -> 0 | AG14: =AE14+AF14-J12 -> -98310 | AH14: =IFERROR((K12-H12)/K12,0) -> 0 | AI14: =IFERROR(AG14/(1-AH14),0) -> -98310 | AJ14: =IFERROR(AG14/H12,0) -> -3.39 | AP14: =IFERROR(AN14/AO14,0) -> 0 | AS14: =IFERROR(((AR14-(AP14*AQ14))/AR14),0) -> 0 | AT14: =IFERROR((AR14/AQ14)*AO14,0) -> 0
B15: 매출이익 | C15: =C5-C13 -> 5228260 | E15: 10 | F15: 냉)흰다리새우 | G15: 20-30 | H15: 184000 | I15: 1.09 | J15: =H15*I15 -> 200560 | L15: =IF(H15="","",H15/0.7) -> 262857.14 | N15: 10 | O15: 고등어 | P15: 30미 | Q15: 45000 | R15: 1.66 | S15: =Q15*R15 -> 74700 | U15: =IF(Q15="","",Q15/0.7) -> 64285.714 | X15: 8 | Y15: =F13&G13 -> 냉)쭈꾸미100-150 | Z15: =J13 -> 210000 | AC15: 8 | AD15: =F13&G13 -> 냉)쭈꾸미100-150 | AE15: =IFERROR(VLOOKUP(AD15,이월!$W$8:$X$69,2,0),0) -> 0 | AF15: =IFERROR(VLOOKUP(AD15,$K$51:$L$85,2,0),0) -> 0 | AG15: =AE15+AF15-J13 -> -210000 | AH15: =IFERROR((K13-H13)/K13,0) -> 0 | AI15: =IFERROR(AG15/(1-AH15),0) -> -210000 | AJ15: =IFERROR(AG15/H13,0) -> -3 | AP15: =IFERROR(AN15/AO15,0) -> 0 | AS15: =IFERROR(((AR15-(AP15*AQ15))/AR15),0) -> 0 | AT15: =IFERROR((AR15/AQ15)*AO15,0) -> 0
E16: 11 | F16: 냉)꽁치 | H16: 46000 | I16: 2 | J16: =H16*I16 -> 92000 | L16: =IF(H16="","",H16/0.7) -> 65714.286 | N16: 11 | O16: 대구 | P16: 4미B | Q16: 19000 | R16: 1 | S16: =Q16*R16 -> 19000 | U16: =IF(Q16="","",Q16/0.7) -> 27142.857 | X16: 9 | Y16: =F14&G14 -> 냉)부세150-200A | Z16: =J14 -> 105000 | AC16: 9 | AD16: =F14&G14 -> 냉)부세150-200A | AE16: =IFERROR(VLOOKUP(AD16,이월!$W$8:$X$69,2,0),0) -> 0 | AF16: =IFERROR(VLOOKUP(AD16,$K$51:$L$85,2,0),0) -> 0 | AG16: =AE16+AF16-J14 -> -105000 | AH16: =IFERROR((K14-H14)/K14,0) -> 0 | AI16: =IFERROR(AG16/(1-AH16),0) -> -105000 | AJ16: =IFERROR(AG16/H14,0) -> -3 | AP16: =IFERROR(AN16/AO16,0) -> 0 | AS16: =IFERROR(((AR16-(AP16*AQ16))/AR16),0) -> 0 | AT16: =IFERROR((AR16/AQ16)*AO16,0) -> 0
B17: 이익률 | C17: =IFERROR(C15/C5,0) -> 0 | E17: 12 | F17: 냉)포크오징어 | G17: M | H17: 194000 | I17: 1.04 | J17: =H17*I17 -> 201760 | L17: =IF(H17="","",H17/0.7) -> 277142.86 | N17: 12 | O17: 생합 | Q17: 50000 | R17: 1.76 | S17: =Q17*R17 -> 88000 | U17: =IF(Q17="","",Q17/0.7) -> 71428.571 | X17: 10 | Y17: =F15&G15 -> 냉)흰다리새우20-30 | Z17: =J15 -> 200560 | AC17: 10 | AD17: =F15&G15 -> 냉)흰다리새우20-30 | AE17: =IFERROR(VLOOKUP(AD17,이월!$W$8:$X$69,2,0),0) -> 0 | AF17: =IFERROR(VLOOKUP(AD17,$K$51:$L$85,2,0),0) -> 0 | AG17: =AE17+AF17-J15 -> -200560 | AH17: =IFERROR((K15-H15)/K15,0) -> 0 | AI17: =IFERROR(AG17/(1-AH17),0) -> -200560 | AJ17: =IFERROR(AG17/H15,0) -> -1.09 | AP17: =IFERROR(AN17/AO17,0) -> 0 | AS17: =IFERROR(((AR17-(AP17*AQ17))/AR17),0) -> 0 | AT17: =IFERROR((AR17/AQ17)*AO17,0) -> 0
E18: 13 | F18: 냉)갈치 | G18: 200-300 | H18: 33000 | I18: 2 | J18: =H18*I18 -> 66000 | L18: =IF(H18="","",H18/0.7) -> 47142.857 | N18: 13 | O18: 참소라 | P18: 소 | Q18: 50000 | R18: 1.57 | S18: =Q18*R18 -> 78500 | U18: =IF(Q18="","",Q18/0.7) -> 71428.571 | X18: 11 | Y18: =F16&G16 -> 냉)꽁치 | Z18: =J16 -> 92000 | AC18: 11 | AD18: =F16&G16 -> 냉)꽁치 | AE18: =IFERROR(VLOOKUP(AD18,이월!$W$8:$X$69,2,0),0) -> 0 | AF18: =IFERROR(VLOOKUP(AD18,$K$51:$L$85,2,0),0) -> 0 | AG18: =AE18+AF18-J16 -> -92000 | AH18: =IFERROR((K16-H16)/K16,0) -> 0 | AI18: =IFERROR(AG18/(1-AH18),0) -> -92000 | AJ18: =IFERROR(AG18/H16,0) -> -2 | AP18: =IFERROR(AN18/AO18,0) -> 0 | AS18: =IFERROR(((AR18-(AP18*AQ18))/AR18),0) -> 0 | AT18: =IFERROR((AR18/AQ18)*AO18,0) -> 0
B19: 영업이익 | C19: =C15-C36 -> 5228260 | E19: 14 | F19: 냉)동태 | G19: 4통 | H19: 46000 | I19: 1 | J19: =H19*I19 -> 46000 | L19: =IF(H19="","",H19/0.7) -> 65714.286 | N19: 14 | O19: 낙지 | P19: 10미B | Q19: 24000 | R19: 6 | S19: =Q19*R19 -> 144000 | U19: =IF(Q19="","",Q19/0.7) -> 34285.714 | X19: 12 | Y19: =F17&G17 -> 냉)포크오징어M | Z19: =J17 -> 201760 | AC19: 12 | AD19: =F17&G17 -> 냉)포크오징어M | AE19: =IFERROR(VLOOKUP(AD19,이월!$W$8:$X$69,2,0),0) -> 0 | AF19: =IFERROR(VLOOKUP(AD19,$K$51:$L$85,2,0),0) -> 0 | AG19: =AE19+AF19-J17 -> -201760 | AH19: =IFERROR((K17-H17)/K17,0) -> 0 | AI19: =IFERROR(AG19/(1-AH19),0) -> -201760 | AJ19: =IFERROR(AG19/H17,0) -> -1.04 | AP19: =IFERROR(AN19/AO19,0) -> 0 | AS19: =IFERROR(((AR19-(AP19*AQ19))/AR19),0) -> 0 | AT19: =IFERROR((AR19/AQ19)*AO19,0) -> 0
